Workbook

Sheet Cover
A1: File Name : | B1: PR Tracker
A2: File Opened on : | B2: 46035
A3: File Modified on :
A4: File Closed on :
C10: Links
B11: PR | C11: https://1drv.ms/f/c/69f235c83271dd38/IgA43XEyyDXyIIBp4QEAAAAAAXNZfTHL3eI2h5IO5sn45uw?e=tn74Qd
B12: 2027 Return | C12: https://onedrive.live.com/personal/69f235c83271dd38/_layouts/15/Doc.aspx?sourcedoc=%7B02B31FF8-D318-4A2C-9B56-D044EA2F7503%7D&file=2027%20Canada%20return.xlsx&action=default&mobileredirect=true
B13: Risk Management & Case Study | C13: https://onedrive.live.com/personal/69f235c83271dd38/_layouts/15/doc.aspx?sourcedoc={79bcfe22-bd6d-426e-ad67-00a7960f8323}&action=edit

Sheet poolBreakdown
A1: CRS score range | C1: 46026 | E1: 46041 | G1: 46057 | I1: 46068 | K1: 46082 | M1: 46096 | O1: 46110 | Q1: 46124 | S1: 46152 | U1: 46166 | W1: 46163
A2: 601-1200 | C2: 559 | E2: 677 | F2: =E2-C2 -> 118 | G2: 423 | H2: =G2-E2 -> -254 | I2: 280 | J2: =I2-G2 -> -143 | K2: 258 | L2: =K2-I2 -> -22 | M2: 360 | N2: =M2-K2 -> 102 | O2: 351 | P2: =O2-M2 -> -9 | Q2: 325 | R2: =Q2-O2 -> -26 | S2: 372 | T2: =S2-Q2 -> 47 | U2: 332 | V2: =U2-S2 -> -40 | W2: 941 | X2: =W2-U2 -> 609
A3: 501-600 | C3: 21013 | E3: 16341 | F3: =E3-C3 -> -4672 | G3: 14911 | H3: =G3-E3 -> -1430 | I3: 16559 | J3: =I3-G3 -> 1648 | K3: 14031 | L3: =K3-I3 -> -2528 | M3: 13039 | N3: =M3-K3 -> -992 | O3: 11648 | P3: =O3-M3 -> -1391 | Q3: 13610 | R3: =Q3-O3 -> 1962 | S3: 15659 | T3: =S3-Q3 -> 2049 | U3: 17945 | V3: =U3-S3 -> 2286 | W3: 20012 | X3: =W3-U3 -> 2067
A4: 451-500 | C4: 70523 | E4: 72714 | F4: =E4-C4 -> 2191 | G4: 74811 | H4: =G4-E4 -> 2097 | I4: 73609 | J4: =I4-G4 -> -1202 | K4: 71680 | L4: =K4-I4 -> -1929 | M4: 72558 | N4: =M4-K4 -> 878 | O4: 73445 | P4: =O4-M4 -> 887 | Q4: 73563 | R4: =Q4-O4 -> 118 | S4: 74300 | T4: =S4-Q4 -> 737 | U4: 75348 | V4: =U4-S4 -> 1048 | W4: 75938 | X4: =W4-U4 -> 590
B5: 491-500 | C5: 12873 | E5: 13278 | F5: =E5-C5 -> 405 | G5: 13586 | H5: =G5-E5 -> 308 | I5: 13504 | J5: =I5-G5 -> -82 | K5: 13321 | L5: =K5-I5 -> -183 | M5: 13421 | N5: =M5-K5 -> 100 | O5: 13558 | P5: =O5-M5 -> 137 | Q5: 13174 | R5: =Q5-O5 -> -384 | S5: 13325 | T5: =S5-Q5 -> 151 | U5: 13449 | V5: =U5-S5 -> 124 | W5: 13537 | X5: =W5-U5 -> 88
B6: 481-490 | C6: 12499 | E6: 12942 | F6: =E6-C6 -> 443 | G6: 13417 | H6: =G6-E6 -> 475 | I6: 13248 | J6: =I6-G6 -> -169 | K6: 12678 | L6: =K6-I6 -> -570 | M6: 12992 | N6: =M6-K6 -> 314 | O6: 13075 | P6: =O6-M6 -> 83 | Q6: 12663 | R6: =Q6-O6 -> -412 | S6: 13109 | T6: =S6-Q6 -> 446 | U6: 13323 | V6: =U6-S6 -> 214 | W6: 13598 | X6: =W6-U6 -> 275
B7: 471-480 | C7: 15435 | E7: 15965 | F7: =E7-C7 -> 530 | G7: 16617 | H7: =G7-E7 -> 652 | I7: 16531 | J7: =I7-G7 -> -86 | K7: 15415 | L7: =K7-I7 -> -1116 | M7: 15751 | N7: =M7-K7 -> 336 | O7: 16153 | P7: =O7-M7 -> 402 | Q7: 16246 | R7: =Q7-O7 -> 93 | S7: 16598 | T7: =S7-Q7 -> 352 | U7: 17040 | V7: =U7-S7 -> 442 | W7: 17318 | X7: =W7-U7 -> 278
B8: 461-470 | C8: 14881 | E8: 15320 | F8: =E8-C8 -> 439 | G8: 15791 | H8: =G8-E8 -> 471 | I8: 15426 | J8: =I8-G8 -> -365 | K8: 15099 | L8: =K8-I8 -> -327 | M8: 15272 | N8: =M8-K8 -> 173 | O8: 15421 | P8: =O8-M8 -> 149 | Q8: 15968 | R8: =Q8-O8 -> 547 | S8: 16160 | T8: =S8-Q8 -> 192 | U8: 16262 | V8: =U8-S8 -> 102 | W8: 16358 | X8: =W8-U8 -> 96
B9: 451-460 | C9: 14835 | E9: 15209 | F9: =E9-C9 -> 374 | G9: 15400 | H9: =G9-E9 -> 191 | I9: 14900 | J9: =I9-G9 -> -500 | K9: 15167 | L9: =K9-I9 -> 267 | M9: 15122 | N9: =M9-K9 -> -45 | O9: 15238 | P9: =O9-M9 -> 116 | Q9: 15512 | R9: =Q9-O9 -> 274 | S9: 15108 | T9: =S9-Q9 -> -404 | U9: 15274 | V9: =U9-S9 -> 166 | W9: 15127 | X9: =W9-U9 -> -147
A10: 401-450 | C10: 65120 | E10: 66836 | F10: =E10-C10 -> 1716 | G10: 66836 | H10: =G10-E10 -> 0 | I10: 64305 | J10: =I10-G10 -> -2531 | K10: 65868 | L10: =K10-I10 -> 1563 | M10: 64638 | N10: =M10-K10 -> -1230 | O10: 64782 | P10: =O10-M10 -> 144 | Q10: 66952 | R10: =Q10-O10 -> 2170 | S10: 64614 | T10: =S10-Q10 -> -2338 | U10: 65963 | V10: =U10-S10 -> 1349 | W10: 64807 | X10: =W10-U10 -> -1156
B11: 441-450 | C11: 14139 | E11: 14452 | F11: =E11-C11 -> 313 | G11: 14452 | H11: =G11-E11 -> 0 | I11: 14142 | J11: =I11-G11 -> -310 | K11: 14334 | L11: =K11-I11 -> 192 | M11: 14195 | N11: =M11-K11 -> -139 | O11: 14173 | P11: =O11-M11 -> -22 | Q11: 14606 | R11: =Q11-O11 -> 433 | S11: 14247 | T11: =S11-Q11 -> -359 | U11: 14463 | V11: =U11-S11 -> 216 | W11: 14147 | X11: =W11-U11 -> -316
B12: 431-440 | C12: 14285 | E12: 14571 | F12: =E12-C12 -> 286 | G12: 14571 | H12: =G12-E12 -> 0 | I12: 14239 | J12: =I12-G12 -> -332 | K12: 14481 | L12: =K12-I12 -> 242 | M12: 14247 | N12: =M12-K12 -> -234 | O12: 14334 | P12: =O12-M12 -> 87 | Q12: 14775 | R12: =Q12-O12 -> 441 | S12: 14171 | T12: =S12-Q12 -> -604 | U12: 14401 | V12: =U12-S12 -> 230 | W12: 13980 | X12: =W12-U12 -> -421
B13: 421-430 | C13: 12816 | E13: 13092 | F13: =E13-C13 -> 276 | G13: 13092 | H13: =G13-E13 -> 0 | I13: 12425 | J13: =I13-G13 -> -667 | K13: 12746 | L13: =K13-I13 -> 321 | M13: 12471 | N13: =M13-K13 -> -275 | O13: 12433 | P13: =O13-M13 -> -38 | Q13: 12973 | R13: =Q13-O13 -> 540 | S13: 12709 | T13: =S13-Q13 -> -264 | U13: 12915 | V13: =U13-S13 -> 206 | W13: 12584 | X13: =W13-U13 -> -331
B14: 411-420 | C14: 12442 | E14: 12863 | F14: =E14-C14 -> 421 | G14: 12863 | H14: =G14-E14 -> 0 | I14: 12183 | J14: =I14-G14 -> -680 | K14: 12511 | L14: =K14-I14 -> 328 | M14: 12288 | N14: =M14-K14 -> -223 | O14: 12348 | P14: =O14-M14 -> 60 | Q14: 12753 | R14: =Q14-O14 -> 405 | S14: 12096 | T14: =S14-Q14 -> -657 | U14: 12402 | V14: =U14-S14 -> 306 | W14: 12128 | X14: =W14-U14 -> -274
B15: 401-410 | C15: 11438 | E15: 11858 | F15: =E15-C15 -> 420 | G15: 11858 | H15: =G15-E15 -> 0 | I15: 11316 | J15: =I15-G15 -> -542 | K15: 11796 | L15: =K15-I15 -> 480 | M15: 11437 | N15: =M15-K15 -> -359 | O15: 11494 | P15: =O15-M15 -> 57 | Q15: 11845 | R15: =Q15-O15 -> 351 | S15: 11391 | T15: =S15-Q15 -> -454 | U15: 11782 | V15: =U15-S15 -> 391 | W15: 11968 | X15: =W15-U15 -> 186
A16: 351-400 | C16: 52469 | E16: 53221 | F16: =E16-C16 -> 752 | G16: 53221 | H16: =G16-E16 -> 0 | I16: 53650 | J16: =I16-G16 -> 429 | K16: 53727 | L16: =K16-I16 -> 77 | M16: 53565 | N16: =M16-K16 -> -162 | O16: 52655 | P16: =O16-M16 -> -910 | Q16: 52309 | R16: =Q16-O16 -> -346 | S16: 52286 | T16: =S16-Q16 -> -23 | U16: 52581 | V16: =U16-S16 -> 295 | W16: 51897 | X16: =W16-U16 -> -684
A17: 301-350 | C17: 18745 | E17: 19062 | F17: =E17-C17 -> 317 | G17: 19062 | H17: =G17-E17 -> 0 | I17: 19009 | J17: =I17-G17 -> -53 | K17: 18694 | L17: =K17-I17 -> -315 | M17: 18903 | N17: =M17-K17 -> 209 | O17: 19007 | P17: =O17-M17 -> 104 | Q17: 18543 | R17: =Q17-O17 -> -464 | S17: 18247 | T17: =S17-Q17 -> -296 | U17: 18375 | V17: =U17-S17 -> 128 | W17: 17946 | X17: =W17-U17 -> -429
A18: 0-300 | C18: 8125 | E18: 8269 | F18: =E18-C18 -> 144 | G18: 8269 | H18: =G18-E18 -> 0 | I18: 8283 | J18: =I18-G18 -> 14 | K18: 8276 | L18: =K18-I18 -> -7 | M18: 8299 | N18: =M18-K18 -> 23 | O18: 8298 | P18: =O18-M18 -> -1 | Q18: 8253 | R18: =Q18-O18 -> -45 | S18: 8292 | T18: =S18-Q18 -> 39 | U18: 8303 | V18: =U18-S18 -> 11 | W18: 8104 | X18: =W18-U18 -> -199
A19: Total | C19: 236554 | E19: 237120 | F19: =E19-C19 -> 566 | G19: 237120 | H19: =G19-E19 -> 0 | I19: 235695 | J19: =I19-G19 -> -1425 | K19: 232534 | L19: =K19-I19 -> -3161 | M19: 231362 | N19: =M19-K19 -> -1172 | O19: 230186 | P19: =O19-M19 -> -1176 | Q19: 233555 | R19: =Q19-O19 -> 3369 | S19: 233770 | T19: =S19-Q19 -> 215 | U19: 238847 | V19: =U19-S19 -> 5077 | W19: 239645 | X19: =W19-U19 -> 798
A23: https://www.canada.ca/en/immigration-refugees-citizenship/services/immigrate-canada/express-entry/rounds-invitations.html | B23: https://www.canada.ca/en/immigration-refugees-citizenship/services/immigrate-canada/express-entry/rounds-invitations.html
A33: Increment | C33: {=_xlfn.CHOOSECOLS(C1:BH1,_xlfn.SEQUENCE(1,D54,1,2))} -> 46026 | D33: 46041 | E33: 46057 | F33: 46068 | G33: 46082 | H33: 46096 | I33: 46110 | J33: 46124 | K33: 46152 | L33: 46166 | M33: 46163
A34: 601-1200 | B34: 601-1200 | C34: {=IF(A33="Pool",_xlfn.CHOOSECOLS(C2:DD19,_xlfn.SEQUENCE(1,D54,1,2)),_xlfn.CHOOSECOLS(D2:DE19,_xlfn.SEQUENCE(1,D54,1,2)))} -> 0 | D34: 118 | E34: -254 | F34: -143 | G34: -22 | H34: 102 | I34: -9 | J34: -26 | K34: 47 | L34: -40 | M34: 609
A35: 501-600 | B35: 501-600 | C35: 0 | D35: -4672 | E35: -1430 | F35: 1648 | G35: -2528 | H35: -992 | I35: -1391 | J35: 1962 | K35: 2049 | L35: 2286 | M35: 2067
A36: 451-500 | B36: 451-500 | C36: 0 | D36: 2191 | E36: 2097 | F36: -1202 | G36: -1929 | H36: 878 | I36: 887 | J36: 118 | K36: 737 | L36: 1048 | M36: 590
A37: 401-450 | B37: 491-500 | C37: 0 | D37: 405 | E37: 308 | F37: -82 | G37: -183 | H37: 100 | I37: 137 | J37: -384 | K37: 151 | L37: 124 | M37: 88
A38: 351-400 | B38: 481-490 | C38: 0 | D38: 443 | E38: 475 | F38: -169 | G38: -570 | H38: 314 | I38: 83 | J38: -412 | K38: 446 | L38: 214 | M38: 275
A39: 301-350 | B39: 471-480 | C39: 0 | D39: 530 | E39: 652 | F39: -86 | G39: -1116 | H39: 336 | I39: 402 | J39: 93 | K39: 352 | L39: 442 | M39: 278
A40: 0-300 | B40: 461-470 | C40: 0 | D40: 439 | E40: 471 | F40: -365 | G40: -327 | H40: 173 | I40: 149 | J40: 547 | K40: 192 | L40: 102 | M40: 96
A41: Total | B41: 451-460 | C41: 0 | D41: 374 | E41: 191 | F41: -500 | G41: 267 | H41: -45 | I41: 116 | J41: 274 | K41: -404 | L41: 166 | M41: -147
A42: 491-500 | B42: 401-450 | C42: 0 | D42: 1716 | E42: 0 | F42: -2531 | G42: 1563 | H42: -1230 | I42: 144 | J42: 2170 | K42: -2338 | L42: 1349 | M42: -1156
A43: 481-490 | B43: 441-450 | C43: 0 | D43: 313 | E43: 0 | F43: -310 | G43: 192 | H43: -139 | I43: -22 | J43: 433 | K43: -359 | L43: 216 | M43: -316
A44: 471-480 | B44: 431-440 | C44: 0 | D44: 286 | E44: 0 | F44: -332 | G44: 242 | H44: -234 | I44: 87 | J44: 441 | K44: -604 | L44: 230 | M44: -421
A45: 461-470 | B45: 421-430 | C45: 0 | D45: 276 | E45: 0 | F45: -667 | G45: 321 | H45: -275 | I45: -38 | J45: 540 | K45: -264 | L45: 206 | M45: -331
A46: 451-460 | B46: 411-420 | C46: 0 | D46: 421 | E46: 0 | F46: -680 | G46: 328 | H46: -223 | I46: 60 | J46: 405 | K46: -657 | L46: 306 | M46: -274
... A51: 401-410 | B51: Total | C51: 0 | D51: 566 | E51: 0 | F51: -1425 | G51: -3161 | H51: -1172 | I51: -1176 | J51: 3369 | K51: 215 | L51: 5077 | M51: 798
A53: 451-500
A54: Date | B54: Value | C54: Change | D54: =MAX(D55:D100)-1 -> 11
A55: {=_xlfn._xlws.FILTER(TRANSPOSE(_xlfn.CHOOSECOLS(C1:BZ1,_xlfn.SEQUENCE(1,30,1,2))),TRANSPOSE(_xlfn.CHOOSECOLS(C1:BZ1,_xlfn.SEQUENCE(1,30,1,2)))<>0)} -> 46026 | B55: =IF(ISBLANK(A55),"",VLOOKUP($A$53,$B$34:$AZ$51,_xlfn.XLOOKUP(A55,$A$55:$A$100,$D$55:$D$100),0)) -> 0 | C55: 0 | D55: 2
A56: 46041 | B56: =IF(ISBLANK(A56),"",VLOOKUP($A$53,$B$34:$AZ$51,_xlfn.XLOOKUP(A56,$A$55:$A$100,$D$55:$D$100),0)) -> 2191 | C56: =IF(ISBLANK(A56),"",B56-B55) -> 2191 | D56: =IF(A56>0,D55+1,"") -> 3
A57: 46057 | B57: =IF(ISBLANK(A57),"",VLOOKUP($A$53,$B$34:$AZ$51,_xlfn.XLOOKUP(A57,$A$55:$A$100,$D$55:$D$100),0)) -> 2097 | C57: =IF(ISBLANK(A57),"",B57-B56) -> -94 | D57: =IF(A57>0,D56+1,"") -> 4
...

Sheet Rounds
A1: # | B1: Date | C1: Round type | D1: Invitations issued | E1: CRS score of lowest-ranked candidate invited | F1: Year
A2: 1 | B2: 42035 | C2: No Program Specified | D2: 779 | E2: 886 | F2: =YEAR(Table1[[#This Row],[Date]]) -> 2015
A3: 2 | B3: 42042 | C3: No Program Specified | D3: 779 | E3: 818 | F3: =YEAR(Table1[[#This Row],[Date]]) -> 2015
A4: 3 | B4: 42055 | C4: Canadian Experience Class | D4: 849 | E4: 808 | F4: =YEAR(Table1[[#This Row],[Date]]) -> 2015
A5: 4 | B5: 42062 | C5: No Program Specified | D5: 1187 | E5: 735 | F5: =YEAR(Table1[[#This Row],[Date]]) -> 2015
A6: 5 | B6: 42083 | C6: No Program Specified | D6: 1620 | E6: 481 | F6: =YEAR(Table1[[#This Row],[Date]]) -> 2015
A7: 6 | B7: 42090 | C7: No Program Specified | D7: 1637 | E7: 453 | F7: =YEAR(Table1[[#This Row],[Date]]) -> 2015
A8: 7 | B8: 42104 | C8: No Program Specified | D8: 925 | E8: 469 | F8: =YEAR(Table1[[#This Row],[Date]]) -> 2015
A9: 8 | B9: 42111 | C9: No Program Specified | D9: 715 | E9: 453 | F9: =YEAR(Table1[[#This Row],[Date]]) -> 2015
A10: 9 | B10: 42146 | C10: No Program Specified | D10: 1361 | E10: 755 | F10: =YEAR(Table1[[#This Row],[Date]]) -> 2015
A11: 10 | B11: 42167 | C11: No Program Specified | D11: 1501 | E11: 482 | F11: =YEAR(Table1[[#This Row],[Date]]) -> 2015
A12: 11 | B12: 42181 | C12: No Program Specified | D12: 1575 | E12: 469 | F12: =YEAR(Table1[[#This Row],[Date]]) -> 2015
A13: 12 | B13: 42195 | C13: No Program Specified | D13: 1516 | E13: 463 | F13: =YEAR(Table1[[#This Row],[Date]]) -> 2015
... A91: 90 | B91: 43243 | C91: No Program Specified | D91: 3500 | E91: 440 | F91: =YEAR(Table1[[#This Row],[Date]]) -> 2018
A92: 91a | B92: 43250 | C92: Federal Skilled Trades | D92: 500 | E92: 288 | F92: =YEAR(Table1[[#This Row],[Date]]) -> 2018
A93: 91b | B93: 43250 | C93: Provincial Nominee Program | D93: 200 | E93: 902 | F93: =YEAR(Table1[[#This Row],[Date]]) -> 2018
A94: 92 | B94: 43264 | C94: No Program Specified | D94: 3750 | E94: 451 | F94: =YEAR(Table1[[#This Row],[Date]]) -> 2018
A95: 93 | B95: 43276 | C95: No Program Specified | D95: 3750 | E95: 442 | F95: =YEAR(Table1[[#This Row],[Date]]) -> 2018
A96: 94 | B96: 43292 | C96: No Program Specified | D96: 3750 | E96: 442 | F96: =YEAR(Table1[[#This Row],[Date]]) -> 2018
A97: 95 | B97: 43306 | C97: No Program Specified | D97: 3750 | E97: 441 | F97: =YEAR(Table1[[#This Row],[Date]]) -> 2018
A98: 96 | B98: 43320 | C98: No Program Specified | D98: 3750 | E98: 440 | F98: =YEAR(Table1[[#This Row],[Date]]) -> 2018
A99: 97 | B99: 43334 | C99: No Program Specified | D99: 3750 | E99: 440 | F99: =YEAR(Table1[[#This Row],[Date]]) -> 2018
A100: 98 | B100: 43348 | C100: No Program Specified | D100: 3900 | E100: 440 | F100: =YEAR(Table1[[#This Row],[Date]]) -> 2018
A101: 99 | B101: 43362 | C101: No Program Specified | D101: 3500 | E101: 441 | F101: =YEAR(Table1[[#This Row],[Date]]) -> 2018
A102: 100 | B102: 43367 | C102: Federal Skilled Trades | D102: 400 | E102: 284 | F102: =YEAR(Table1[[#This Row],[Date]]) -> 2018
A103: 101 | B103: 43376 | C103: No Program Specified | D103: 3900 | E103: 445 | F103: =YEAR(Table1[[#This Row],[Date]]) -> 2018
A104: 102 | B104: 43388 | C104: No Program Specified | D104: 3900 | E104: 440 | F104: =YEAR(Table1[[#This Row],[Date]]) -> 2018
A105: 103 | B105: 43402 | C105: No Program Specified | D105: 3900 | E105: 442 | F105: =YEAR(Table1[[#This Row],[Date]]) -> 2018
... A421: 419 | B421: 46195 | C421: Provincial Nominee Program | D421: 955 | E421: 730 | F421: =YEAR(Table1[[#This Row],[Date]]) -> 2026
F422: =YEAR(Table1[[#This Row],[Date]]) -> 1900
F423: =YEAR(Table1[[#This Row],[Date]]) -> 1900
F424: =YEAR(Table1[[#This Row],[Date]]) -> 1900
F425: =YEAR(Table1[[#This Row],[Date]]) -> 1900
F426: =YEAR(Table1[[#This Row],[Date]]) -> 1900
F427: =YEAR(Table1[[#This Row],[Date]]) -> 1900
F428: =YEAR(Table1[[#This Row],[Date]]) -> 1900
F429: =YEAR(Table1[[#This Row],[Date]]) -> 1900
F430: =YEAR(Table1[[#This Row],[Date]]) -> 1900
F431: =YEAR(Table1[[#This Row],[Date]]) -> 1900
F432: =YEAR(Table1[[#This Row],[Date]]) -> 1900
...

Sheet targetCheck
B1: =YEAR(TODAY()) -> 2026 | C1: =B1-1 -> 2025 | D1: =C1-1 -> 2024 | E1: =D1-1 -> 2023 | F1: =E1-1 -> 2022 | G1: =F1-1 -> 2021 | H1: =G1-1 -> 2020 | I1: =H1-1 -> 2019 | J1: =I1-1 -> 2018 | ... P1: =O1-1 -> 2012
A2: Target | B2: 109000 | C2: 109000 | D2: 110770
A3: Current Total | B3: =SUM(B6:B30) -> 75391 | C3: =SUM(C6:C30) -> 103100 | D3: =SUM(D6:D30) -> 83420 | E3: =SUM(E6:E30) -> 105870 | F3: =SUM(F6:F30) -> 35750 | G3: =SUM(G6:G30) -> 0 | H3: =SUM(H6:H30) -> 0 | I3: =SUM(I6:I30) -> 0 | ... O3: =SUM(O6:O30) -> 0
A4: Others | B4: 0 | C4: 0 | D4: 0 | E4: 0
A5: Balance | B5: =B2-(B3+B4) -> 33609 | C5: =C2-(C3+C4) -> 5900 | D5: =D2-(D3+D4) -> 27350 | E5: =E2-(E3+E4) -> -105870 | F5: =F2-(F3+F4) -> -35750 | G5: =G2-(G3+G4) -> 0 | H5: =H2-(H3+H4) -> 0 | I5: =I2-(I3+I4) -> 0 | ... P5: =P2-(P3+P4) -> 0
A6: {=_xlfn._xlws.FILTER(TC!S2:S29,TC!T2:T29="Yes")} -> Canadian Experience Class | B6: =SUMIFS(Rounds!$D$2:$D$1000,Rounds!$C$2:$C$1000,targetCheck!A6,Rounds!$F$2:$F$1000,$B$1) -> 37250 | C6: =SUMIFS(Rounds!$D$2:$D$1000,Rounds!$C$2:$C$1000,targetCheck!A6,Rounds!$F$2:$F$1000,$C$1) -> 35850 | D6: =SUMIFS(Rounds!$D$2:$D$1000,Rounds!$C$2:$C$1000,targetCheck!A6,Rounds!$F$2:$F$1000,$D$1) -> 26500 | E6: =SUMIFS(Rounds!$D$2:$D$1000,Rounds!$C$2:$C$1000,targetCheck!A6,Rounds!$F$2:$F$1000,$E$1) -> 0 | F6: =SUMIFS(Rounds!$D$2:$D$1000,Rounds!$C$2:$C$1000,targetCheck!A6,Rounds!$F$2:$F$1000,$F$1) -> 0
A7: Healthcare and social services occupations (Version 2) | B7: =SUMIFS(Rounds!$D$2:$D$1000,Rounds!$C$2:$C$1000,targetCheck!A7,Rounds!$F$2:$F$1000,$B$1) -> 0 | C7: =SUMIFS(Rounds!$D$2:$D$1000,Rounds!$C$2:$C$1000,targetCheck!A7,Rounds!$F$2:$F$1000,$C$1) -> 14500 | D7: =SUMIFS(Rounds!$D$2:$D$1000,Rounds!$C$2:$C$1000,targetCheck!A7,Rounds!$F$2:$F$1000,$D$1) -> 0 | E7: =SUMIFS(Rounds!$D$2:$D$1000,Rounds!$C$2:$C$1000,targetCheck!A7,Rounds!$F$2:$F$1000,$E$1) -> 0 | F7: =SUMIFS(Rounds!$D$2:$D$1000,Rounds!$C$2:$C$1000,targetCheck!A7,Rounds!$F$2:$F$1000,$F$1) -> 0
A8: Senior managers with Canadian Work Experience, 2026-Version 1 | B8: =SUMIFS(Rounds!$D$2:$D$1000,Rounds!$C$2:$C$1000,targetCheck!A8,Rounds!$F$2:$F$1000,$B$1) -> 250 | C8: =SUMIFS(Rounds!$D$2:$D$1000,Rounds!$C$2:$C$1000,targetCheck!A8,Rounds!$F$2:$F$1000,$C$1) -> 0 | D8: =SUMIFS(Rounds!$D$2:$D$1000,Rounds!$C$2:$C$1000,targetCheck!A8,Rounds!$F$2:$F$1000,$D$1) -> 0 | E8: =SUMIFS(Rounds!$D$2:$D$1000,Rounds!$C$2:$C$1000,targetCheck!A8,Rounds!$F$2:$F$1000,$E$1) -> 0 | F8: =SUMIFS(Rounds!$D$2:$D$1000,Rounds!$C$2:$C$1000,targetCheck!A8,Rounds!$F$2:$F$1000,$F$1) -> 0
A9: STEM occupations (Version 1) | B9: =SUMIFS(Rounds!$D$2:$D$1000,Rounds!$C$2:$C$1000,targetCheck!A9,Rounds!$F$2:$F$1000,$B$1) -> 0 | C9: =SUMIFS(Rounds!$D$2:$D$1000,Rounds!$C$2:$C$1000,targetCheck!A9,Rounds!$F$2:$F$1000,$C$1) -> 0 | D9: =SUMIFS(Rounds!$D$2:$D$1000,Rounds!$C$2:$C$1000,targetCheck!A9,Rounds!$F$2:$F$1000,$D$1) -> 4500 | E9: =SUMIFS(Rounds!$D$2:$D$1000,Rounds!$C$2:$C$1000,targetCheck!A9,Rounds!$F$2:$F$1000,$E$1) -> 6400 | F9: =SUMIFS(Rounds!$D$2:$D$1000,Rounds!$C$2:$C$1000,targetCheck!A9,Rounds!$F$2:$F$1000,$F$1) -> 0
A10: Trade occupations (Version 1) | B10: =SUMIFS(Rounds!$D$2:$D$1000,Rounds!$C$2:$C$1000,targetCheck!A10,Rounds!$F$2:$F$1000,$B$1) -> 0 | C10: =SUMIFS(Rounds!$D$2:$D$1000,Rounds!$C$2:$C$1000,targetCheck!A10,Rounds!$F$2:$F$1000,$C$1) -> 0 | D10: =SUMIFS(Rounds!$D$2:$D$1000,Rounds!$C$2:$C$1000,targetCheck!A10,Rounds!$F$2:$F$1000,$D$1) -> 3600 | E10: =SUMIFS(Rounds!$D$2:$D$1000,Rounds!$C$2:$C$1000,targetCheck!A10,Rounds!$F$2:$F$1000,$E$1) -> 2500 | F10: =SUMIFS(Rounds!$D$2:$D$1000,Rounds!$C$2:$C$1000,targetCheck!A10,Rounds!$F$2:$F$1000,$F$1) -> 0
A11: Trade occupations (Version 2) | B11: =SUMIFS(Rounds!$D$2:$D$1000,Rounds!$C$2:$C$1000,targetCheck!A11,Rounds!$F$2:$F$1000,$B$1) -> 0 | C11: =SUMIFS(Rounds!$D$2:$D$1000,Rounds!$C$2:$C$1000,targetCheck!A11,Rounds!$F$2:$F$1000,$C$1) -> 1250 | D11: =SUMIFS(Rounds!$D$2:$D$1000,Rounds!$C$2:$C$1000,targetCheck!A11,Rounds!$F$2:$F$1000,$D$1) -> 0 | E11: =SUMIFS(Rounds!$D$2:$D$1000,Rounds!$C$2:$C$1000,targetCheck!A11,Rounds!$F$2:$F$1000,$E$1) -> 0 | F11: =SUMIFS(Rounds!$D$2:$D$1000,Rounds!$C$2:$C$1000,targetCheck!A11,Rounds!$F$2:$F$1000,$F$1) -> 0
A12: Trades Occupations, 2026-Version 3 | B12: =SUMIFS(Rounds!$D$2:$D$1000,Rounds!$C$2:$C$1000,targetCheck!A12,Rounds!$F$2:$F$1000,$B$1) -> 3000 | C12: =SUMIFS(Rounds!$D$2:$D$1000,Rounds!$C$2:$C$1000,targetCheck!A12,Rounds!$F$2:$F$1000,$C$1) -> 0 | D12: =SUMIFS(Rounds!$D$2:$D$1000,Rounds!$C$2:$C$1000,targetCheck!A12,Rounds!$F$2:$F$1000,$D$1) -> 0 | E12: =SUMIFS(Rounds!$D$2:$D$1000,Rounds!$C$2:$C$1000,targetCheck!A12,Rounds!$F$2:$F$1000,$E$1) -> 0 | F12: =SUMIFS(Rounds!$D$2:$D$1000,Rounds!$C$2:$C$1000,targetCheck!A12,Rounds!$F$2:$F$1000,$F$1) -> 0
A13: Education occupations (Version 1) | B13: =SUMIFS(Rounds!$D$2:$D$1000,Rounds!$C$2:$C$1000,targetCheck!A13,Rounds!$F$2:$F$1000,$B$1) -> 0 | C13: =SUMIFS(Rounds!$D$2:$D$1000,Rounds!$C$2:$C$1000,targetCheck!A13,Rounds!$F$2:$F$1000,$C$1) -> 3500 | D13: =SUMIFS(Rounds!$D$2:$D$1000,Rounds!$C$2:$C$1000,targetCheck!A13,Rounds!$F$2:$F$1000,$D$1) -> 0 | E13: =SUMIFS(Rounds!$D$2:$D$1000,Rounds!$C$2:$C$1000,targetCheck!A13,Rounds!$F$2:$F$1000,$E$1) -> 0 | F13: =SUMIFS(Rounds!$D$2:$D$1000,Rounds!$C$2:$C$1000,targetCheck!A13,Rounds!$F$2:$F$1000,$F$1) -> 0
A14: Agriculture and agri-food occupations (Version 1) | B14: =SUMIFS(Rounds!$D$2:$D$1000,Rounds!$C$2:$C$1000,targetCheck!A14,Rounds!$F$2:$F$1000,$B$1) -> 0 | C14: =SUMIFS(Rounds!$D$2:$D$1000,Rounds!$C$2:$C$1000,targetCheck!A14,Rounds!$F$2:$F$1000,$C$1) -> 0 | D14: =SUMIFS(Rounds!$D$2:$D$1000,Rounds!$C$2:$C$1000,targetCheck!A14,Rounds!$F$2:$F$1000,$D$1) -> 150 | E14: =SUMIFS(Rounds!$D$2:$D$1000,Rounds!$C$2:$C$1000,targetCheck!A14,Rounds!$F$2:$F$1000,$E$1) -> 1000 | F14: =SUMIFS(Rounds!$D$2:$D$1000,Rounds!$C$2:$C$1000,targetCheck!A14,Rounds!$F$2:$F$1000,$F$1) -> 0
A15: Federal Skilled Trades | B15: =SUMIFS(Rounds!$D$2:$D$1000,Rounds!$C$2:$C$1000,targetCheck!A15,Rounds!$F$2:$F$1000,$B$1) -> 0 | C15: =SUMIFS(Rounds!$D$2:$D$1000,Rounds!$C$2:$C$1000,targetCheck!A15,Rounds!$F$2:$F$1000,$C$1) -> 0 | D15: =SUMIFS(Rounds!$D$2:$D$1000,Rounds!$C$2:$C$1000,targetCheck!A15,Rounds!$F$2:$F$1000,$D$1) -> 0 | E15: =SUMIFS(Rounds!$D$2:$D$1000,Rounds!$C$2:$C$1000,targetCheck!A15,Rounds!$F$2:$F$1000,$E$1) -> 0 | F15: =SUMIFS(Rounds!$D$2:$D$1000,Rounds!$C$2:$C$1000,targetCheck!A15,Rounds!$F$2:$F$1000,$F$1) -> 0
A16: Federal Skilled Worker | B16: =SUMIFS(Rounds!$D$2:$D$1000,Rounds!$C$2:$C$1000,targetCheck!A16,Rounds!$F$2:$F$1000,$B$1) -> 0 | C16: =SUMIFS(Rounds!$D$2:$D$1000,Rounds!$C$2:$C$1000,targetCheck!A16,Rounds!$F$2:$F$1000,$C$1) -> 0 | D16: =SUMIFS(Rounds!$D$2:$D$1000,Rounds!$C$2:$C$1000,targetCheck!A16,Rounds!$F$2:$F$1000,$D$1) -> 0 | E16: =SUMIFS(Rounds!$D$2:$D$1000,Rounds!$C$2:$C$1000,targetCheck!A16,Rounds!$F$2:$F$1000,$E$1) -> 3300 | F16: =SUMIFS(Rounds!$D$2:$D$1000,Rounds!$C$2:$C$1000,targetCheck!A16,Rounds!$F$2:$F$1000,$F$1) -> 0
A17: French language proficiency (Version 1) | B17: =SUMIFS(Rounds!$D$2:$D$1000,Rounds!$C$2:$C$1000,targetCheck!A17,Rounds!$F$2:$F$1000,$B$1) -> 0 | C17: =SUMIFS(Rounds!$D$2:$D$1000,Rounds!$C$2:$C$1000,targetCheck!A17,Rounds!$F$2:$F$1000,$C$1) -> 48000 | D17: =SUMIFS(Rounds!$D$2:$D$1000,Rounds!$C$2:$C$1000,targetCheck!A17,Rounds!$F$2:$F$1000,$D$1) -> 23000 | E17: =SUMIFS(Rounds!$D$2:$D$1000,Rounds!$C$2:$C$1000,targetCheck!A17,Rounds!$F$2:$F$1000,$E$1) -> 8700 | F17: =SUMIFS(Rounds!$D$2:$D$1000,Rounds!$C$2:$C$1000,targetCheck!A17,Rounds!$F$2:$F$1000,$F$1) -> 0
A18: French-Language proficiency 2026-Version 2 | B18: =SUMIFS(Rounds!$D$2:$D$1000,Rounds!$C$2:$C$1000,targetCheck!A18,Rounds!$F$2:$F$1000,$B$1) -> 30500 | C18: =SUMIFS(Rounds!$D$2:$D$1000,Rounds!$C$2:$C$1000,targetCheck!A18,Rounds!$F$2:$F$1000,$C$1) -> 0 | D18: =SUMIFS(Rounds!$D$2:$D$1000,Rounds!$C$2:$C$1000,targetCheck!A18,Rounds!$F$2:$F$1000,$D$1) -> 0 | E18: =SUMIFS(Rounds!$D$2:$D$1000,Rounds!$C$2:$C$1000,targetCheck!A18,Rounds!$F$2:$F$1000,$E$1) -> 0 | F18: =SUMIFS(Rounds!$D$2:$D$1000,Rounds!$C$2:$C$1000,targetCheck!A18,Rounds!$F$2:$F$1000,$F$1) -> 0
... A24: Transport occupations (Version 1) | B24: =SUMIFS(Rounds!$D$2:$D$1000,Rounds!$C$2:$C$1000,targetCheck!A24,Rounds!$F$2:$F$1000,$B$1) -> 0 | C24: =SUMIFS(Rounds!$D$2:$D$1000,Rounds!$C$2:$C$1000,targetCheck!A24,Rounds!$F$2:$F$1000,$C$1) -> 0 | D24: =SUMIFS(Rounds!$D$2:$D$1000,Rounds!$C$2:$C$1000,targetCheck!A24,Rounds!$F$2:$F$1000,$D$1) -> 975 | E24: =SUMIFS(Rounds!$D$2:$D$1000,Rounds!$C$2:$C$1000,targetCheck!A24,Rounds!$F$2:$F$1000,$E$1) -> 1670 | F24: =SUMIFS(Rounds!$D$2:$D$1000,Rounds!$C$2:$C$1000,targetCheck!A24,Rounds!$F$2:$F$1000,$F$1) -> 0
B25: =SUMIFS(Rounds!$D$2:$D$1000,Rounds!$C$2:$C$1000,targetCheck!A25,Rounds!$F$2:$F$1000,$B$1) -> 0 | C25: =SUMIFS(Rounds!$D$2:$D$1000,Rounds!$C$2:$C$1000,targetCheck!A25,Rounds!$F$2:$F$1000,$C$1) -> 0 | D25: =SUMIFS(Rounds!$D$2:$D$1000,Rounds!$C$2:$C$1000,targetCheck!A25,Rounds!$F$2:$F$1000,$D$1) -> 0 | E25: =SUMIFS(Rounds!$D$2:$D$1000,Rounds!$C$2:$C$1000,targetCheck!A25,Rounds!$F$2:$F$1000,$E$1) -> 0 | F25: =SUMIFS(Rounds!$D$2:$D$1000,Rounds!$C$2:$C$1000,targetCheck!A25,Rounds!$F$2:$F$1000,$F$1) -> 0

Sheet CEC
A1: # | B1: Date | C1: Round type | D1: Invitations issued | E1: CRS score of lowest-ranked candidate invited | F1: Year | G1: Canadian Experience Class | J1: 2026
A2: {=_xlfn._xlws.SORT(_xlfn._xlws.FILTER(Rounds!A2:F1036,((Rounds!C2:C1036=CEC!G1)*(Rounds!F2:F1036=CEC!J1))),VLOOKUP(J2,TC!O2:P5,2,0),VLOOKUP(CEC!J3,TC!F2:G3,2,0))} -> 390 | B2: 46029 | C2: Canadian Experience Class | D2: 8000 | E2: 511 | F2: 2026 | I2: Sort by | J2: Date
A3: 392 | B3: 46043 | C3: Canadian Experience Class | D3: 6000 | E3: 509 | F3: 2026 | I3: Order | J3: Ascending
A4: 396 | B4: 46070 | C4: Canadian Experience Class | D4: 6000 | E4: 508 | F4: 2026
A5: 400 | B5: 46084 | C5: Canadian Experience Class | D5: 4000 | E5: 508 | F5: 2026
A6: 404 | B6: 46098 | C6: Canadian Experience Class | D6: 4000 | E6: 507 | F6: 2026
A7: 407 | B7: 46112 | C7: Canadian Experience Class | D7: 2250 | E7: 509 | F7: 2026
A8: 410 | B8: 46126 | C8: Canadian Experience Class | D8: 2000 | E8: 515 | F8: 2026
A9: 413 | B9: 46140 | C9: Canadian Experience Class | D9: 2000 | E9: 514 | F9: 2026
A10: 417 | B10: 46169 | C10: Canadian Experience Class | D10: 3000 | E10: 518 | F10: 2026

Sheet Language points
B1: Celpip 7 | C1: Ielts 7 | D1: Ielts - 8 | E1: Ielts - 9
A2: Speaking | B2: 7 | C2: 6.5 | D2: 7 | E2: 7
A3: Listening | B3: 9 | C3: 7 | D3: 7.5 | E3: 8
A4: Reading | B4: 8 | C4: 7 | D4: 7 to 7.5 | E4: 7 to 7.5
A5: Writing | B5: 8 | C5: 7 | D5: 7 | E5: 7
A6: Points | B6: 493 | C6: 501 | D6: 515 | E6: 535 | F6: =535+12 -> 547
A9: 1 year foreigin wrk exp and 33 age

Sheet CEC_Count
A1: Sort | B1: Year | C1: Order | D1: Descending | E1: Canadian Experience Class | O1: Year | P1: Count | Q1: Invitations | R1: CRS minimum
A2: {=_xlfn._xlws.SORT(O2:R16,VLOOKUP(B1,TC!C10:D13,2,0),VLOOKUP(CEC_Count!D1,TC!F2:G3,2,0))} -> 2026 | B2: 9 | C2: 37250 | D2: 507 | O2: {=_xlfn._xlws.SORT(_xlfn.UNIQUE(Rounds!F2:F1036),,-1)} -> 2026 | P2: =COUNTIFS(Rounds!$C$2:$C$1036,CEC_Count!$E$1,Rounds!$F$2:$F$1036,CEC_Count!O2) -> 9 | Q2: =SUMIFS(Rounds!$D$2:$D$1036,Rounds!$F$2:$F$1036,CEC_Count!O2,Rounds!$C$2:$C$1036,CEC_Count!$E$1) -> 37250 | R2: =_xlfn.MINIFS(Rounds!$E$2:$E$1036,Rounds!$F$2:$F$1036,CEC_Count!O2,Rounds!$C$2:$C$1036,CEC_Count!$E$1) -> 507
A3: 2025 | B3: 15 | C3: 35850 | D3: 515 | O3: 2025 | P3: =COUNTIFS(Rounds!$C$2:$C$1036,CEC_Count!$E$1,Rounds!$F$2:$F$1036,CEC_Count!O3) -> 15 | Q3: =SUMIFS(Rounds!$D$2:$D$1036,Rounds!$F$2:$F$1036,CEC_Count!O3,Rounds!$C$2:$C$1036,CEC_Count!$E$1) -> 35850 | R3: =_xlfn.MINIFS(Rounds!$E$2:$E$1036,Rounds!$F$2:$F$1036,CEC_Count!O3,Rounds!$C$2:$C$1036,CEC_Count!$E$1) -> 515
A4: 2024 | B4: 10 | C4: 26500 | D4: 507 | O4: 2024 | P4: =COUNTIFS(Rounds!$C$2:$C$1036,CEC_Count!$E$1,Rounds!$F$2:$F$1036,CEC_Count!O4) -> 10 | Q4: =SUMIFS(Rounds!$D$2:$D$1036,Rounds!$F$2:$F$1036,CEC_Count!O4,Rounds!$C$2:$C$1036,CEC_Count!$E$1) -> 26500 | R4: =_xlfn.MINIFS(Rounds!$E$2:$E$1036,Rounds!$F$2:$F$1036,CEC_Count!O4,Rounds!$C$2:$C$1036,CEC_Count!$E$1) -> 507
A5: 2023 | B5: 0 | C5: 0 | D5: 0 | O5: 2023 | P5: =COUNTIFS(Rounds!$C$2:$C$1036,CEC_Count!$E$1,Rounds!$F$2:$F$1036,CEC_Count!O5) -> 0 | Q5: =SUMIFS(Rounds!$D$2:$D$1036,Rounds!$F$2:$F$1036,CEC_Count!O5,Rounds!$C$2:$C$1036,CEC_Count!$E$1) -> 0 | R5: =_xlfn.MINIFS(Rounds!$E$2:$E$1036,Rounds!$F$2:$F$1036,CEC_Count!O5,Rounds!$C$2:$C$1036,CEC_Count!$E$1) -> 0
A6: 2022 | B6: 0 | C6: 0 | D6: 0 | O6: 2022 | P6: =COUNTIFS(Rounds!$C$2:$C$1036,CEC_Count!$E$1,Rounds!$F$2:$F$1036,CEC_Count!O6) -> 0 | Q6: =SUMIFS(Rounds!$D$2:$D$1036,Rounds!$F$2:$F$1036,CEC_Count!O6,Rounds!$C$2:$C$1036,CEC_Count!$E$1) -> 0 | R6: =_xlfn.MINIFS(Rounds!$E$2:$E$1036,Rounds!$F$2:$F$1036,CEC_Count!O6,Rounds!$C$2:$C$1036,CEC_Count!$E$1) -> 0
A7: 2021 | B7: 17 | C7: 99653 | D7: 75 | O7: 2021 | P7: =COUNTIFS(Rounds!$C$2:$C$1036,CEC_Count!$E$1,Rounds!$F$2:$F$1036,CEC_Count!O7) -> 17 | Q7: =SUMIFS(Rounds!$D$2:$D$1036,Rounds!$F$2:$F$1036,CEC_Count!O7,Rounds!$C$2:$C$1036,CEC_Count!$E$1) -> 99653 | R7: =_xlfn.MINIFS(Rounds!$E$2:$E$1036,Rounds!$F$2:$F$1036,CEC_Count!O7,Rounds!$C$2:$C$1036,CEC_Count!$E$1) -> 75
A8: 2020 | B8: 10 | C8: 34215 | D8: 431 | O8: 2020 | P8: =COUNTIFS(Rounds!$C$2:$C$1036,CEC_Count!$E$1,Rounds!$F$2:$F$1036,CEC_Count!O8) -> 10 | Q8: =SUMIFS(Rounds!$D$2:$D$1036,Rounds!$F$2:$F$1036,CEC_Count!O8,Rounds!$C$2:$C$1036,CEC_Count!$E$1) -> 34215 | R8: =_xlfn.MINIFS(Rounds!$E$2:$E$1036,Rounds!$F$2:$F$1036,CEC_Count!O8,Rounds!$C$2:$C$1036,CEC_Count!$E$1) -> 431
A9: 2019 | B9: 0 | C9: 0 | D9: 0 | O9: 2019 | P9: =COUNTIFS(Rounds!$C$2:$C$1036,CEC_Count!$E$1,Rounds!$F$2:$F$1036,CEC_Count!O9) -> 0 | Q9: =SUMIFS(Rounds!$D$2:$D$1036,Rounds!$F$2:$F$1036,CEC_Count!O9,Rounds!$C$2:$C$1036,CEC_Count!$E$1) -> 0 | R9: =_xlfn.MINIFS(Rounds!$E$2:$E$1036,Rounds!$F$2:$F$1036,CEC_Count!O9,Rounds!$C$2:$C$1036,CEC_Count!$E$1) -> 0
A10: 2018 | B10: 0 | C10: 0 | D10: 0 | O10: 2018 | P10: =COUNTIFS(Rounds!$C$2:$C$1036,CEC_Count!$E$1,Rounds!$F$2:$F$1036,CEC_Count!O10) -> 0 | Q10: =SUMIFS(Rounds!$D$2:$D$1036,Rounds!$F$2:$F$1036,CEC_Count!O10,Rounds!$C$2:$C$1036,CEC_Count!$E$1) -> 0 | R10: =_xlfn.MINIFS(Rounds!$E$2:$E$1036,Rounds!$F$2:$F$1036,CEC_Count!O10,Rounds!$C$2:$C$1036,CEC_Count!$E$1) -> 0
A11: 2017 | B11: 0 | C11: 0 | D11: 0 | O11: 2017 | P11: =COUNTIFS(Rounds!$C$2:$C$1036,CEC_Count!$E$1,Rounds!$F$2:$F$1036,CEC_Count!O11) -> 0 | Q11: =SUMIFS(Rounds!$D$2:$D$1036,Rounds!$F$2:$F$1036,CEC_Count!O11,Rounds!$C$2:$C$1036,CEC_Count!$E$1) -> 0 | R11: =_xlfn.MINIFS(Rounds!$E$2:$E$1036,Rounds!$F$2:$F$1036,CEC_Count!O11,Rounds!$C$2:$C$1036,CEC_Count!$E$1) -> 0
A12: 2016 | B12: 0 | C12: 0 | D12: 0 | O12: 2016 | P12: =COUNTIFS(Rounds!$C$2:$C$1036,CEC_Count!$E$1,Rounds!$F$2:$F$1036,CEC_Count!O12) -> 0 | Q12: =SUMIFS(Rounds!$D$2:$D$1036,Rounds!$F$2:$F$1036,CEC_Count!O12,Rounds!$C$2:$C$1036,CEC_Count!$E$1) -> 0 | R12: =_xlfn.MINIFS(Rounds!$E$2:$E$1036,Rounds!$F$2:$F$1036,CEC_Count!O12,Rounds!$C$2:$C$1036,CEC_Count!$E$1) -> 0
A13: 2015 | B13: 1 | C13: 849 | D13: 808 | O13: 2015 | P13: =COUNTIFS(Rounds!$C$2:$C$1036,CEC_Count!$E$1,Rounds!$F$2:$F$1036,CEC_Count!O13) -> 1 | Q13: =SUMIFS(Rounds!$D$2:$D$1036,Rounds!$F$2:$F$1036,CEC_Count!O13,Rounds!$C$2:$C$1036,CEC_Count!$E$1) -> 849 | R13: =_xlfn.MINIFS(Rounds!$E$2:$E$1036,Rounds!$F$2:$F$1036,CEC_Count!O13,Rounds!$C$2:$C$1036,CEC_Count!$E$1) -> 808
A14: 1900 | B14: 0 | C14: 0 | D14: 0 | O14: 1900 | P14: =COUNTIFS(Rounds!$C$2:$C$1036,CEC_Count!$E$1,Rounds!$F$2:$F$1036,CEC_Count!O14) -> 0 | Q14: =SUMIFS(Rounds!$D$2:$D$1036,Rounds!$F$2:$F$1036,CEC_Count!O14,Rounds!$C$2:$C$1036,CEC_Count!$E$1) -> 0 | R14: =_xlfn.MINIFS(Rounds!$E$2:$E$1036,Rounds!$F$2:$F$1036,CEC_Count!O14,Rounds!$C$2:$C$1036,CEC_Count!$E$1) -> 0
A15: 0 | B15: 0 | C15: 0 | D15: 0 | O15: 0 | P15: =COUNTIFS(Rounds!$C$2:$C$1036,CEC_Count!$E$1,Rounds!$F$2:$F$1036,CEC_Count!O15) -> 0 | Q15: =SUMIFS(Rounds!$D$2:$D$1036,Rounds!$F$2:$F$1036,CEC_Count!O15,Rounds!$C$2:$C$1036,CEC_Count!$E$1) -> 0 | R15: =_xlfn.MINIFS(Rounds!$E$2:$E$1036,Rounds!$F$2:$F$1036,CEC_Count!O15,Rounds!$C$2:$C$1036,CEC_Count!$E$1) -> 0
A16: 0 | B16: 0 | C16: 0 | D16: 0

Sheet Analysis
A1: Year | B1: 2023 | C1: Sort | D1: Invitations | E1: Order | F1: Descending | L1: Year | M1: =B1 -> 2023
A2: Round Type | B2: Count | C2: Invitations | D2: CRS minimum | E2: CRA Max | L2: Round Type | M2: Count | N2: Invitations | O2: CRS minimum | P2: CRA Max
A3: {=_xlfn._xlws.SORT(L3:P17,VLOOKUP(D1,TC!C2:D6,2,FALSE),VLOOKUP(F1,TC!F2:G3,2,0))} -> No Program Specified | B3: 17 | C3: 70625 | D3: 481 | E3: 531 | L3: Agriculture and agri-food occupations (Version 1) | M3: =COUNTIFS(Rounds!$C$2:$C$1036,Analysis!L3,Rounds!$F$2:$F$1036,Analysis!$M$1) -> 2 | N3: =SUMIFS(Rounds!$D$2:$D$1036,Rounds!$C$2:$C$1036,Analysis!L3,Rounds!$F$2:$F$1036,$M$1) -> 1000 | O3: =_xlfn.MINIFS(Rounds!$E$2:$E$1036,Rounds!$C$2:$C$1036,Analysis!L3,Rounds!$F$2:$F$1036,Analysis!$M$1) -> 354 | P3: =_xlfn.MAXIFS(Rounds!$E$2:$E$1036,Rounds!$C$2:$C$1036,Analysis!L3,Rounds!$F$2:$F$1036,Analysis!$M$1) -> 386 | R3: Max Invitations | S3: =_xlfn.XLOOKUP(T3,N3:N17,L3:L17) -> No Program Specified | T3: =MAX(N3:N17) -> 70625
A4: French language proficiency (Version 1) | B4: 6 | C4: 8700 | D4: 375 | E4: 486 | L4: Canadian Experience Class | M4: =COUNTIFS(Rounds!$C$2:$C$1036,Analysis!L4,Rounds!$F$2:$F$1036,Analysis!$M$1) -> 0 | N4: =SUMIFS(Rounds!$D$2:$D$1036,Rounds!$C$2:$C$1036,Analysis!L4,Rounds!$F$2:$F$1036,$M$1) -> 0 | O4: =_xlfn.MINIFS(Rounds!$E$2:$E$1036,Rounds!$C$2:$C$1036,Analysis!L4,Rounds!$F$2:$F$1036,Analysis!$M$1) -> 0 | P4: =_xlfn.MAXIFS(Rounds!$E$2:$E$1036,Rounds!$C$2:$C$1036,Analysis!L4,Rounds!$F$2:$F$1036,Analysis!$M$1) -> 0 | R4: Min Invitaiotns | S4: =_xlfn.XLOOKUP(T4,N3:N17,L3:L17) -> Agriculture and agri-food occupations (Version 1) | T4: =_xlfn.MINIFS(N3:N17,N3:N17,">0") -> 1000
A5: STEM occupations (Version 1) | B5: 2 | C5: 6400 | D5: 481 | E5: 486 | L5: Education occupations (Version 1) | M5: =COUNTIFS(Rounds!$C$2:$C$1036,Analysis!L5,Rounds!$F$2:$F$1036,Analysis!$M$1) -> 0 | N5: =SUMIFS(Rounds!$D$2:$D$1036,Rounds!$C$2:$C$1036,Analysis!L5,Rounds!$F$2:$F$1036,$M$1) -> 0 | O5: =_xlfn.MINIFS(Rounds!$E$2:$E$1036,Rounds!$C$2:$C$1036,Analysis!L5,Rounds!$F$2:$F$1036,Analysis!$M$1) -> 0 | P5: =_xlfn.MAXIFS(Rounds!$E$2:$E$1036,Rounds!$C$2:$C$1036,Analysis!L5,Rounds!$F$2:$F$1036,Analysis!$M$1) -> 0
A6: General | B6: 2 | C6: 6075 | D6: 542 | E6: 561 | L6: Federal Skilled Trades | M6: =COUNTIFS(Rounds!$C$2:$C$1036,Analysis!L6,Rounds!$F$2:$F$1036,Analysis!$M$1) -> 0 | N6: =SUMIFS(Rounds!$D$2:$D$1036,Rounds!$C$2:$C$1036,Analysis!L6,Rounds!$F$2:$F$1036,$M$1) -> 0 | O6: =_xlfn.MINIFS(Rounds!$E$2:$E$1036,Rounds!$C$2:$C$1036,Analysis!L6,Rounds!$F$2:$F$1036,Analysis!$M$1) -> 0 | P6: =_xlfn.MAXIFS(Rounds!$E$2:$E$1036,Rounds!$C$2:$C$1036,Analysis!L6,Rounds!$F$2:$F$1036,Analysis!$M$1) -> 0 | R6: Max No. | S6: =_xlfn.XLOOKUP(T6,M3:M17,L3:L17) -> No Program Specified | T6: =MAX(M3:M17) -> 17
A7: Healthcare occupations (Version 1) | B7: 3 | C7: 5600 | D7: 431 | E7: 476 | L7: Federal Skilled Worker | M7: =COUNTIFS(Rounds!$C$2:$C$1036,Analysis!L7,Rounds!$F$2:$F$1036,Analysis!$M$1) -> 1 | N7: =SUMIFS(Rounds!$D$2:$D$1036,Rounds!$C$2:$C$1036,Analysis!L7,Rounds!$F$2:$F$1036,$M$1) -> 3300 | O7: =_xlfn.MINIFS(Rounds!$E$2:$E$1036,Rounds!$C$2:$C$1036,Analysis!L7,Rounds!$F$2:$F$1036,Analysis!$M$1) -> 489 | P7: =_xlfn.MAXIFS(Rounds!$E$2:$E$1036,Rounds!$C$2:$C$1036,Analysis!L7,Rounds!$F$2:$F$1036,Analysis!$M$1) -> 489 | R7: Min No. | S7: =_xlfn.XLOOKUP(T7,M3:M17,L3:L17) -> Federal Skilled Worker | T7: =_xlfn.MINIFS(M3:M17,M3:M17,">0") -> 1
A8: Provincial Nominee Program | B8: 5 | C8: 4396 | D8: 691 | E8: 791 | L8: French language proficiency (Version 1) | M8: =COUNTIFS(Rounds!$C$2:$C$1036,Analysis!L8,Rounds!$F$2:$F$1036,Analysis!$M$1) -> 6 | N8: =SUMIFS(Rounds!$D$2:$D$1036,Rounds!$C$2:$C$1036,Analysis!L8,Rounds!$F$2:$F$1036,$M$1) -> 8700 | O8: =_xlfn.MINIFS(Rounds!$E$2:$E$1036,Rounds!$C$2:$C$1036,Analysis!L8,Rounds!$F$2:$F$1036,Analysis!$M$1) -> 375 | P8: =_xlfn.MAXIFS(Rounds!$E$2:$E$1036,Rounds!$C$2:$C$1036,Analysis!L8,Rounds!$F$2:$F$1036,Analysis!$M$1) -> 486
A9: Federal Skilled Worker | B9: 1 | C9: 3300 | D9: 489 | E9: 489 | L9: General | M9: =COUNTIFS(Rounds!$C$2:$C$1036,Analysis!L9,Rounds!$F$2:$F$1036,Analysis!$M$1) -> 2 | N9: =SUMIFS(Rounds!$D$2:$D$1036,Rounds!$C$2:$C$1036,Analysis!L9,Rounds!$F$2:$F$1036,$M$1) -> 6075 | O9: =_xlfn.MINIFS(Rounds!$E$2:$E$1036,Rounds!$C$2:$C$1036,Analysis!L9,Rounds!$F$2:$F$1036,Analysis!$M$1) -> 542 | P9: =_xlfn.MAXIFS(Rounds!$E$2:$E$1036,Rounds!$C$2:$C$1036,Analysis!L9,Rounds!$F$2:$F$1036,Analysis!$M$1) -> 561
A10: Trade occupations (Version 1) | B10: 2 | C10: 2500 | D10: 388 | E10: 425 | L10: Healthcare and social services occupations (Version 2) | M10: =COUNTIFS(Rounds!$C$2:$C$1036,Analysis!L10,Rounds!$F$2:$F$1036,Analysis!$M$1) -> 0 | N10: =SUMIFS(Rounds!$D$2:$D$1036,Rounds!$C$2:$C$1036,Analysis!L10,Rounds!$F$2:$F$1036,$M$1) -> 0 | O10: =_xlfn.MINIFS(Rounds!$E$2:$E$1036,Rounds!$C$2:$C$1036,Analysis!L10,Rounds!$F$2:$F$1036,Analysis!$M$1) -> 0 | P10: =_xlfn.MAXIFS(Rounds!$E$2:$E$1036,Rounds!$C$2:$C$1036,Analysis!L10,Rounds!$F$2:$F$1036,Analysis!$M$1) -> 0 | S10: Canadian Experience Class | T10: =VLOOKUP(S10,L3:N17,3,0) -> 0
A11: Transport occupations (Version 1) | B11: 2 | C11: 1670 | D11: 435 | E11: 435 | L11: Healthcare occupations (Version 1) | M11: =COUNTIFS(Rounds!$C$2:$C$1036,Analysis!L11,Rounds!$F$2:$F$1036,Analysis!$M$1) -> 3 | N11: =SUMIFS(Rounds!$D$2:$D$1036,Rounds!$C$2:$C$1036,Analysis!L11,Rounds!$F$2:$F$1036,$M$1) -> 5600 | O11: =_xlfn.MINIFS(Rounds!$E$2:$E$1036,Rounds!$C$2:$C$1036,Analysis!L11,Rounds!$F$2:$F$1036,Analysis!$M$1) -> 431 | P11: =_xlfn.MAXIFS(Rounds!$E$2:$E$1036,Rounds!$C$2:$C$1036,Analysis!L11,Rounds!$F$2:$F$1036,Analysis!$M$1) -> 476 | T11: =VLOOKUP(S10,L3:M17,2,0) -> 0
A12: Agriculture and agri-food occupations (Version 1) | B12: 2 | C12: 1000 | D12: 354 | E12: 386 | L12: No Program Specified | M12: =COUNTIFS(Rounds!$C$2:$C$1036,Analysis!L12,Rounds!$F$2:$F$1036,Analysis!$M$1) -> 17 | N12: =SUMIFS(Rounds!$D$2:$D$1036,Rounds!$C$2:$C$1036,Analysis!L12,Rounds!$F$2:$F$1036,$M$1) -> 70625 | O12: =_xlfn.MINIFS(Rounds!$E$2:$E$1036,Rounds!$C$2:$C$1036,Analysis!L12,Rounds!$F$2:$F$1036,Analysis!$M$1) -> 481 | P12: =_xlfn.MAXIFS(Rounds!$E$2:$E$1036,Rounds!$C$2:$C$1036,Analysis!L12,Rounds!$F$2:$F$1036,Analysis!$M$1) -> 531
A13: Canadian Experience Class | B13: 0 | C13: 0 | D13: 0 | E13: 0 | L13: Provincial Nominee Program | M13: =COUNTIFS(Rounds!$C$2:$C$1036,Analysis!L13,Rounds!$F$2:$F$1036,Analysis!$M$1) -> 5 | N13: =SUMIFS(Rounds!$D$2:$D$1036,Rounds!$C$2:$C$1036,Analysis!L13,Rounds!$F$2:$F$1036,$M$1) -> 4396 | O13: =_xlfn.MINIFS(Rounds!$E$2:$E$1036,Rounds!$C$2:$C$1036,Analysis!L13,Rounds!$F$2:$F$1036,Analysis!$M$1) -> 691 | P13: =_xlfn.MAXIFS(Rounds!$E$2:$E$1036,Rounds!$C$2:$C$1036,Analysis!L13,Rounds!$F$2:$F$1036,Analysis!$M$1) -> 791
A14: Education occupations (Version 1) | B14: 0 | C14: 0 | D14: 0 | E14: 0 | L14: STEM occupations (Version 1) | M14: =COUNTIFS(Rounds!$C$2:$C$1036,Analysis!L14,Rounds!$F$2:$F$1036,Analysis!$M$1) -> 2 | N14: =SUMIFS(Rounds!$D$2:$D$1036,Rounds!$C$2:$C$1036,Analysis!L14,Rounds!$F$2:$F$1036,$M$1) -> 6400 | O14: =_xlfn.MINIFS(Rounds!$E$2:$E$1036,Rounds!$C$2:$C$1036,Analysis!L14,Rounds!$F$2:$F$1036,Analysis!$M$1) -> 481 | P14: =_xlfn.MAXIFS(Rounds!$E$2:$E$1036,Rounds!$C$2:$C$1036,Analysis!L14,Rounds!$F$2:$F$1036,Analysis!$M$1) -> 486
A15: Federal Skilled Trades | B15: 0 | C15: 0 | D15: 0 | E15: 0 | L15: Trade occupations (Version 1) | M15: =COUNTIFS(Rounds!$C$2:$C$1036,Analysis!L15,Rounds!$F$2:$F$1036,Analysis!$M$1) -> 2 | N15: =SUMIFS(Rounds!$D$2:$D$1036,Rounds!$C$2:$C$1036,Analysis!L15,Rounds!$F$2:$F$1036,$M$1) -> 2500 | O15: =_xlfn.MINIFS(Rounds!$E$2:$E$1036,Rounds!$C$2:$C$1036,Analysis!L15,Rounds!$F$2:$F$1036,Analysis!$M$1) -> 388 | P15: =_xlfn.MAXIFS(Rounds!$E$2:$E$1036,Rounds!$C$2:$C$1036,Analysis!L15,Rounds!$F$2:$F$1036,Analysis!$M$1) -> 425
A16: Healthcare and social services occupations (Version 2) | B16: 0 | C16: 0 | D16: 0 | E16: 0 | L16: Trade occupations (Version 2) | M16: =COUNTIFS(Rounds!$C$2:$C$1036,Analysis!L16,Rounds!$F$2:$F$1036,Analysis!$M$1) -> 0 | N16: =SUMIFS(Rounds!$D$2:$D$1036,Rounds!$C$2:$C$1036,Analysis!L16,Rounds!$F$2:$F$1036,$M$1) -> 0 | O16: =_xlfn.MINIFS(Rounds!$E$2:$E$1036,Rounds!$C$2:$C$1036,Analysis!L16,Rounds!$F$2:$F$1036,Analysis!$M$1) -> 0 | P16: =_xlfn.MAXIFS(Rounds!$E$2:$E$1036,Rounds!$C$2:$C$1036,Analysis!L16,Rounds!$F$2:$F$1036,Analysis!$M$1) -> 0
A17: Trade occupations (Version 2) | B17: 0 | C17: 0 | D17: 0 | E17: 0 | L17: Transport occupations (Version 1) | M17: =COUNTIFS(Rounds!$C$2:$C$1036,Analysis!L17,Rounds!$F$2:$F$1036,Analysis!$M$1) -> 2 | N17: =SUMIFS(Rounds!$D$2:$D$1036,Rounds!$C$2:$C$1036,Analysis!L17,Rounds!$F$2:$F$1036,$M$1) -> 1670 | O17: =_xlfn.MINIFS(Rounds!$E$2:$E$1036,Rounds!$C$2:$C$1036,Analysis!L17,Rounds!$F$2:$F$1036,Analysis!$M$1) -> 435 | P17: =_xlfn.MAXIFS(Rounds!$E$2:$E$1036,Rounds!$C$2:$C$1036,Analysis!L17,Rounds!$F$2:$F$1036,Analysis!$M$1) -> 435

Sheet Overall
A1: Round Type | B1: Count | C1: Invitations | D1: CRS minimum | E1: CRA Max | H1: =YEAR(TODAY()) -> 2026 | I1: =H1-1 -> 2025 | J1: =I1-1 -> 2024 | K1: =J1-1 -> 2023 | L1: =K1-1 -> 2022 | M1: =L1-1 -> 2021 | N1: =M1-1 -> 2020 | O1: =N1-1 -> 2019 | P1: =O1-1 -> 2018 | ... U1: =T1-1 -> 2013
A2: Agriculture and agri-food occupations (Version 1) | B2: =COUNTIFS(Rounds!$C$2:$C$1036,Overall!A2) -> 3 | C2: =SUMIFS(Rounds!$D$2:$D$1036,Rounds!$C$2:$C$1036,Overall!A2) -> 1150 | D2: =_xlfn.MINIFS(Rounds!$E$2:$E$1036,Rounds!$C$2:$C$1036,Overall!A2) -> 354 | E2: =_xlfn.MAXIFS(Rounds!$E$2:$E$1036,Rounds!$C$2:$C$1036,Overall!A2) -> 437 | H2: =COUNTIFS(Rounds!$C$2:$C$1036,Overall!A2,Rounds!$F$2:$F$1036,Overall!$H$1) -> 0 | I2: =COUNTIFS(Rounds!$C$2:$C$1036,Overall!A2,Rounds!$F$2:$F$1036,Overall!$I$1) -> 0 | J2: =COUNTIFS(Rounds!$C$2:$C$1036,Overall!A2,Rounds!$F$2:$F$1036,Overall!$J$1) -> 1 | K2: =COUNTIFS(Rounds!$C$2:$C$1036,Overall!A2,Rounds!$F$2:$F$1036,Overall!$K$1) -> 2 | L2: =COUNTIFS(Rounds!$C$2:$C$1036,Overall!A2,Rounds!$F$2:$F$1036,Overall!$L$1) -> 0 | M2: =COUNTIFS(Rounds!$C$2:$C$1036,Overall!A2,Rounds!$F$2:$F$1036,Overall!$M$1) -> 0 | N2: =COUNTIFS(Rounds!$C$2:$C$1036,Overall!A2,Rounds!$F$2:$F$1036,Overall!$N$1) -> 0 | O2: =COUNTIFS(Rounds!$C$2:$C$1036,Overall!A2,Rounds!$F$2:$F$1036,Overall!$O$1) -> 0 | P2: =COUNTIFS(Rounds!$C$2:$C$1036,Overall!A2,Rounds!$F$2:$F$1036,Overall!$P$1) -> 0 | Q2: =COUNTIFS(Rounds!$C$2:$C$1036,Overall!A2,Rounds!$F$2:$F$1036,Overall!$Q$1) -> 0 | R2: =COUNTIFS(Rounds!$C$2:$C$1036,Overall!A2,Rounds!$F$2:$F$1036,Overall!$R$1) -> 0 | S2: =COUNTIFS(Rounds!$C$2:$C$1036,Overall!A2,Rounds!$F$2:$F$1036,Overall!$S$1) -> 0 | T2: =COUNTIFS(Rounds!$C$2:$C$1036,Overall!A2,Rounds!$F$2:$F$1036,Overall!$T$1) -> 0 | U2: =COUNTIFS(Rounds!$C$2:$C$1036,Overall!A2,Rounds!$F$2:$F$1036,Overall!$U$1) -> 0
A3: Canadian Experience Class | B3: =COUNTIFS(Rounds!$C$2:$C$1036,Overall!A3) -> 62 | C3: =SUMIFS(Rounds!$D$2:$D$1036,Rounds!$C$2:$C$1036,Overall!A3) -> 234317 | D3: =_xlfn.MINIFS(Rounds!$E$2:$E$1036,Rounds!$C$2:$C$1036,Overall!A3) -> 75 | E3: =_xlfn.MAXIFS(Rounds!$E$2:$E$1036,Rounds!$C$2:$C$1036,Overall!A3) -> 808 | H3: =COUNTIFS(Rounds!$C$2:$C$1036,Overall!A3,Rounds!$F$2:$F$1036,Overall!$H$1) -> 9 | I3: =COUNTIFS(Rounds!$C$2:$C$1036,Overall!A3,Rounds!$F$2:$F$1036,Overall!$I$1) -> 15 | J3: =COUNTIFS(Rounds!$C$2:$C$1036,Overall!A3,Rounds!$F$2:$F$1036,Overall!$J$1) -> 10 | K3: =COUNTIFS(Rounds!$C$2:$C$1036,Overall!A3,Rounds!$F$2:$F$1036,Overall!$K$1) -> 0 | L3: =COUNTIFS(Rounds!$C$2:$C$1036,Overall!A3,Rounds!$F$2:$F$1036,Overall!$L$1) -> 0 | M3: =COUNTIFS(Rounds!$C$2:$C$1036,Overall!A3,Rounds!$F$2:$F$1036,Overall!$M$1) -> 17 | N3: =COUNTIFS(Rounds!$C$2:$C$1036,Overall!A3,Rounds!$F$2:$F$1036,Overall!$N$1) -> 10 | O3: =COUNTIFS(Rounds!$C$2:$C$1036,Overall!A3,Rounds!$F$2:$F$1036,Overall!$O$1) -> 0 | P3: =COUNTIFS(Rounds!$C$2:$C$1036,Overall!A3,Rounds!$F$2:$F$1036,Overall!$P$1) -> 0 | Q3: =COUNTIFS(Rounds!$C$2:$C$1036,Overall!A3,Rounds!$F$2:$F$1036,Overall!$Q$1) -> 0 | R3: =COUNTIFS(Rounds!$C$2:$C$1036,Overall!A3,Rounds!$F$2:$F$1036,Overall!$R$1) -> 0 | S3: =COUNTIFS(Rounds!$C$2:$C$1036,Overall!A3,Rounds!$F$2:$F$1036,Overall!$S$1) -> 1 | T3: =COUNTIFS(Rounds!$C$2:$C$1036,Overall!A3,Rounds!$F$2:$F$1036,Overall!$T$1) -> 0 | U3: =COUNTIFS(Rounds!$C$2:$C$1036,Overall!A3,Rounds!$F$2:$F$1036,Overall!$U$1) -> 0
A4: Education occupations (Version 1) | B4: =COUNTIFS(Rounds!$C$2:$C$1036,Overall!A4) -> 2 | C4: =SUMIFS(Rounds!$D$2:$D$1036,Rounds!$C$2:$C$1036,Overall!A4) -> 3500 | D4: =_xlfn.MINIFS(Rounds!$E$2:$E$1036,Rounds!$C$2:$C$1036,Overall!A4) -> 462 | E4: =_xlfn.MAXIFS(Rounds!$E$2:$E$1036,Rounds!$C$2:$C$1036,Overall!A4) -> 479 | H4: =COUNTIFS(Rounds!$C$2:$C$1036,Overall!A4,Rounds!$F$2:$F$1036,Overall!$H$1) -> 0 | I4: =COUNTIFS(Rounds!$C$2:$C$1036,Overall!A4,Rounds!$F$2:$F$1036,Overall!$I$1) -> 2 | J4: =COUNTIFS(Rounds!$C$2:$C$1036,Overall!A4,Rounds!$F$2:$F$1036,Overall!$J$1) -> 0 | K4: =COUNTIFS(Rounds!$C$2:$C$1036,Overall!A4,Rounds!$F$2:$F$1036,Overall!$K$1) -> 0 | L4: =COUNTIFS(Rounds!$C$2:$C$1036,Overall!A4,Rounds!$F$2:$F$1036,Overall!$L$1) -> 0 | M4: =COUNTIFS(Rounds!$C$2:$C$1036,Overall!A4,Rounds!$F$2:$F$1036,Overall!$M$1) -> 0 | N4: =COUNTIFS(Rounds!$C$2:$C$1036,Overall!A4,Rounds!$F$2:$F$1036,Overall!$N$1) -> 0 | O4: =COUNTIFS(Rounds!$C$2:$C$1036,Overall!A4,Rounds!$F$2:$F$1036,Overall!$O$1) -> 0 | P4: =COUNTIFS(Rounds!$C$2:$C$1036,Overall!A4,Rounds!$F$2:$F$1036,Overall!$P$1) -> 0 | Q4: =COUNTIFS(Rounds!$C$2:$C$1036,Overall!A4,Rounds!$F$2:$F$1036,Overall!$Q$1) -> 0 | R4: =COUNTIFS(Rounds!$C$2:$C$1036,Overall!A4,Rounds!$F$2:$F$1036,Overall!$R$1) -> 0 | S4: =COUNTIFS(Rounds!$C$2:$C$1036,Overall!A4,Rounds!$F$2:$F$1036,Overall!$S$1) -> 0 | T4: =COUNTIFS(Rounds!$C$2:$C$1036,Overall!A4,Rounds!$F$2:$F$1036,Overall!$T$1) -> 0 | U4: =COUNTIFS(Rounds!$C$2:$C$1036,Overall!A4,Rounds!$F$2:$F$1036,Overall!$U$1) -> 0
A5: Federal Skilled Trades | B5: =COUNTIFS(Rounds!$C$2:$C$1036,Overall!A5) -> 7 | C5: =SUMIFS(Rounds!$D$2:$D$1036,Rounds!$C$2:$C$1036,Overall!A5) -> 3055 | D5: =_xlfn.MINIFS(Rounds!$E$2:$E$1036,Rounds!$C$2:$C$1036,Overall!A5) -> 199 | E5: =_xlfn.MAXIFS(Rounds!$E$2:$E$1036,Rounds!$C$2:$C$1036,Overall!A5) -> 415 | H5: =COUNTIFS(Rounds!$C$2:$C$1036,Overall!A5,Rounds!$F$2:$F$1036,Overall!$H$1) -> 0 | I5: =COUNTIFS(Rounds!$C$2:$C$1036,Overall!A5,Rounds!$F$2:$F$1036,Overall!$I$1) -> 0 | J5: =COUNTIFS(Rounds!$C$2:$C$1036,Overall!A5,Rounds!$F$2:$F$1036,Overall!$J$1) -> 0 | K5: =COUNTIFS(Rounds!$C$2:$C$1036,Overall!A5,Rounds!$F$2:$F$1036,Overall!$K$1) -> 0 | L5: =COUNTIFS(Rounds!$C$2:$C$1036,Overall!A5,Rounds!$F$2:$F$1036,Overall!$L$1) -> 0 | M5: =COUNTIFS(Rounds!$C$2:$C$1036,Overall!A5,Rounds!$F$2:$F$1036,Overall!$M$1) -> 0 | N5: =COUNTIFS(Rounds!$C$2:$C$1036,Overall!A5,Rounds!$F$2:$F$1036,Overall!$N$1) -> 1 | O5: =COUNTIFS(Rounds!$C$2:$C$1036,Overall!A5,Rounds!$F$2:$F$1036,Overall!$O$1) -> 2 | P5: =COUNTIFS(Rounds!$C$2:$C$1036,Overall!A5,Rounds!$F$2:$F$1036,Overall!$P$1) -> 2 | Q5: =COUNTIFS(Rounds!$C$2:$C$1036,Overall!A5,Rounds!$F$2:$F$1036,Overall!$Q$1) -> 2 | R5: =COUNTIFS(Rounds!$C$2:$C$1036,Overall!A5,Rounds!$F$2:$F$1036,Overall!$R$1) -> 0 | S5: =COUNTIFS(Rounds!$C$2:$C$1036,Overall!A5,Rounds!$F$2:$F$1036,Overall!$S$1) -> 0 | T5: =COUNTIFS(Rounds!$C$2:$C$1036,Overall!A5,Rounds!$F$2:$F$1036,Overall!$T$1) -> 0 | U5: =COUNTIFS(Rounds!$C$2:$C$1036,Overall!A5,Rounds!$F$2:$F$1036,Overall!$U$1) -> 0
A6: Federal Skilled Worker | B6: =COUNTIFS(Rounds!$C$2:$C$1036,Overall!A6) -> 1 | C6: =SUMIFS(Rounds!$D$2:$D$1036,Rounds!$C$2:$C$1036,Overall!A6) -> 3300 | D6: =_xlfn.MINIFS(Rounds!$E$2:$E$1036,Rounds!$C$2:$C$1036,Overall!A6) -> 489 | E6: =_xlfn.MAXIFS(Rounds!$E$2:$E$1036,Rounds!$C$2:$C$1036,Overall!A6) -> 489 | H6: =COUNTIFS(Rounds!$C$2:$C$1036,Overall!A6,Rounds!$F$2:$F$1036,Overall!$H$1) -> 0 | I6: =COUNTIFS(Rounds!$C$2:$C$1036,Overall!A6,Rounds!$F$2:$F$1036,Overall!$I$1) -> 0 | J6: =COUNTIFS(Rounds!$C$2:$C$1036,Overall!A6,Rounds!$F$2:$F$1036,Overall!$J$1) -> 0 | K6: =COUNTIFS(Rounds!$C$2:$C$1036,Overall!A6,Rounds!$F$2:$F$1036,Overall!$K$1) -> 1 | L6: =COUNTIFS(Rounds!$C$2:$C$1036,Overall!A6,Rounds!$F$2:$F$1036,Overall!$L$1) -> 0 | M6: =COUNTIFS(Rounds!$C$2:$C$1036,Overall!A6,Rounds!$F$2:$F$1036,Overall!$M$1) -> 0 | N6: =COUNTIFS(Rounds!$C$2:$C$1036,Overall!A6,Rounds!$F$2:$F$1036,Overall!$N$1) -> 0 | O6: =COUNTIFS(Rounds!$C$2:$C$1036,Overall!A6,Rounds!$F$2:$F$1036,Overall!$O$1) -> 0 | P6: =COUNTIFS(Rounds!$C$2:$C$1036,Overall!A6,Rounds!$F$2:$F$1036,Overall!$P$1) -> 0 | Q6: =COUNTIFS(Rounds!$C$2:$C$1036,Overall!A6,Rounds!$F$2:$F$1036,Overall!$Q$1) -> 0 | R6: =COUNTIFS(Rounds!$C$2:$C$1036,Overall!A6,Rounds!$F$2:$F$1036,Overall!$R$1) -> 0 | S6: =COUNTIFS(Rounds!$C$2:$C$1036,Overall!A6,Rounds!$F$2:$F$1036,Overall!$S$1) -> 0 | T6: =COUNTIFS(Rounds!$C$2:$C$1036,Overall!A6,Rounds!$F$2:$F$1036,Overall!$T$1) -> 0 | U6: =COUNTIFS(Rounds!$C$2:$C$1036,Overall!A6,Rounds!$F$2:$F$1036,Overall!$U$1) -> 0
A7: French language proficiency (Version 1) | B7: =COUNTIFS(Rounds!$C$2:$C$1036,Overall!A7) -> 26 | C7: =SUMIFS(Rounds!$D$2:$D$1036,Rounds!$C$2:$C$1036,Overall!A7) -> 79700 | D7: =_xlfn.MINIFS(Rounds!$E$2:$E$1036,Rounds!$C$2:$C$1036,Overall!A7) -> 336 | E7: =_xlfn.MAXIFS(Rounds!$E$2:$E$1036,Rounds!$C$2:$C$1036,Overall!A7) -> 486 | H7: =COUNTIFS(Rounds!$C$2:$C$1036,Overall!A7,Rounds!$F$2:$F$1036,Overall!$H$1) -> 0 | I7: =COUNTIFS(Rounds!$C$2:$C$1036,Overall!A7,Rounds!$F$2:$F$1036,Overall!$I$1) -> 9 | J7: =COUNTIFS(Rounds!$C$2:$C$1036,Overall!A7,Rounds!$F$2:$F$1036,Overall!$J$1) -> 11 | K7: =COUNTIFS(Rounds!$C$2:$C$1036,Overall!A7,Rounds!$F$2:$F$1036,Overall!$K$1) -> 6 | L7: =COUNTIFS(Rounds!$C$2:$C$1036,Overall!A7,Rounds!$F$2:$F$1036,Overall!$L$1) -> 0 | M7: =COUNTIFS(Rounds!$C$2:$C$1036,Overall!A7,Rounds!$F$2:$F$1036,Overall!$M$1) -> 0 | N7: =COUNTIFS(Rounds!$C$2:$C$1036,Overall!A7,Rounds!$F$2:$F$1036,Overall!$N$1) -> 0 | O7: =COUNTIFS(Rounds!$C$2:$C$1036,Overall!A7,Rounds!$F$2:$F$1036,Overall!$O$1) -> 0 | P7: =COUNTIFS(Rounds!$C$2:$C$1036,Overall!A7,Rounds!$F$2:$F$1036,Overall!$P$1) -> 0 | Q7: =COUNTIFS(Rounds!$C$2:$C$1036,Overall!A7,Rounds!$F$2:$F$1036,Overall!$Q$1) -> 0 | R7: =COUNTIFS(Rounds!$C$2:$C$1036,Overall!A7,Rounds!$F$2:$F$1036,Overall!$R$1) -> 0 | S7: =COUNTIFS(Rounds!$C$2:$C$1036,Overall!A7,Rounds!$F$2:$F$1036,Overall!$S$1) -> 0 | T7: =COUNTIFS(Rounds!$C$2:$C$1036,Overall!A7,Rounds!$F$2:$F$1036,Overall!$T$1) -> 0 | U7: =COUNTIFS(Rounds!$C$2:$C$1036,Overall!A7,Rounds!$F$2:$F$1036,Overall!$U$1) -> 0
A8: General | B8: =COUNTIFS(Rounds!$C$2:$C$1036,Overall!A8) -> 11 | C8: =SUMIFS(Rounds!$D$2:$D$1036,Rounds!$C$2:$C$1036,Overall!A8) -> 20520 | D8: =_xlfn.MINIFS(Rounds!$E$2:$E$1036,Rounds!$C$2:$C$1036,Overall!A8) -> 524 | E8: =_xlfn.MAXIFS(Rounds!$E$2:$E$1036,Rounds!$C$2:$C$1036,Overall!A8) -> 561 | H8: =COUNTIFS(Rounds!$C$2:$C$1036,Overall!A8,Rounds!$F$2:$F$1036,Overall!$H$1) -> 0 | I8: =COUNTIFS(Rounds!$C$2:$C$1036,Overall!A8,Rounds!$F$2:$F$1036,Overall!$I$1) -> 0 | J8: =COUNTIFS(Rounds!$C$2:$C$1036,Overall!A8,Rounds!$F$2:$F$1036,Overall!$J$1) -> 9 | K8: =COUNTIFS(Rounds!$C$2:$C$1036,Overall!A8,Rounds!$F$2:$F$1036,Overall!$K$1) -> 2 | L8: =COUNTIFS(Rounds!$C$2:$C$1036,Overall!A8,Rounds!$F$2:$F$1036,Overall!$L$1) -> 0 | M8: =COUNTIFS(Rounds!$C$2:$C$1036,Overall!A8,Rounds!$F$2:$F$1036,Overall!$M$1) -> 0 | N8: =COUNTIFS(Rounds!$C$2:$C$1036,Overall!A8,Rounds!$F$2:$F$1036,Overall!$N$1) -> 0 | O8: =COUNTIFS(Rounds!$C$2:$C$1036,Overall!A8,Rounds!$F$2:$F$1036,Overall!$O$1) -> 0 | P8: =COUNTIFS(Rounds!$C$2:$C$1036,Overall!A8,Rounds!$F$2:$F$1036,Overall!$P$1) -> 0 | Q8: =COUNTIFS(Rounds!$C$2:$C$1036,Overall!A8,Rounds!$F$2:$F$1036,Overall!$Q$1) -> 0 | R8: =COUNTIFS(Rounds!$C$2:$C$1036,Overall!A8,Rounds!$F$2:$F$1036,Overall!$R$1) -> 0 | S8: =COUNTIFS(Rounds!$C$2:$C$1036,Overall!A8,Rounds!$F$2:$F$1036,Overall!$S$1) -> 0 | T8: =COUNTIFS(Rounds!$C$2:$C$1036,Overall!A8,Rounds!$F$2:$F$1036,Overall!$T$1) -> 0 | U8: =COUNTIFS(Rounds!$C$2:$C$1036,Overall!A8,Rounds!$F$2:$F$1036,Overall!$U$1) -> 0
A9: Healthcare and social services occupations (Version 2) | B9: =COUNTIFS(Rounds!$C$2:$C$1036,Overall!A9) -> 7 | C9: =SUMIFS(Rounds!$D$2:$D$1036,Rounds!$C$2:$C$1036,Overall!A9) -> 14500 | D9: =_xlfn.MINIFS(Rounds!$E$2:$E$1036,Rounds!$C$2:$C$1036,Overall!A9) -> 462 | E9: =_xlfn.MAXIFS(Rounds!$E$2:$E$1036,Rounds!$C$2:$C$1036,Overall!A9) -> 510 | H9: =COUNTIFS(Rounds!$C$2:$C$1036,Overall!A9,Rounds!$F$2:$F$1036,Overall!$H$1) -> 0 | I9: =COUNTIFS(Rounds!$C$2:$C$1036,Overall!A9,Rounds!$F$2:$F$1036,Overall!$I$1) -> 7 | J9: =COUNTIFS(Rounds!$C$2:$C$1036,Overall!A9,Rounds!$F$2:$F$1036,Overall!$J$1) -> 0 | K9: =COUNTIFS(Rounds!$C$2:$C$1036,Overall!A9,Rounds!$F$2:$F$1036,Overall!$K$1) -> 0 | L9: =COUNTIFS(Rounds!$C$2:$C$1036,Overall!A9,Rounds!$F$2:$F$1036,Overall!$L$1) -> 0 | M9: =COUNTIFS(Rounds!$C$2:$C$1036,Overall!A9,Rounds!$F$2:$F$1036,Overall!$M$1) -> 0 | N9: =COUNTIFS(Rounds!$C$2:$C$1036,Overall!A9,Rounds!$F$2:$F$1036,Overall!$N$1) -> 0 | O9: =COUNTIFS(Rounds!$C$2:$C$1036,Overall!A9,Rounds!$F$2:$F$1036,Overall!$O$1) -> 0 | P9: =COUNTIFS(Rounds!$C$2:$C$1036,Overall!A9,Rounds!$F$2:$F$1036,Overall!$P$1) -> 0 | Q9: =COUNTIFS(Rounds!$C$2:$C$1036,Overall!A9,Rounds!$F$2:$F$1036,Overall!$Q$1) -> 0 | R9: =COUNTIFS(Rounds!$C$2:$C$1036,Overall!A9,Rounds!$F$2:$F$1036,Overall!$R$1) -> 0 | S9: =COUNTIFS(Rounds!$C$2:$C$1036,Overall!A9,Rounds!$F$2:$F$1036,Overall!$S$1) -> 0 | T9: =COUNTIFS(Rounds!$C$2:$C$1036,Overall!A9,Rounds!$F$2:$F$1036,Overall!$T$1) -> 0 | U9: =COUNTIFS(Rounds!$C$2:$C$1036,Overall!A9,Rounds!$F$2:$F$1036,Overall!$U$1) -> 0
A10: Healthcare occupations (Version 1) | B10: =COUNTIFS(Rounds!$C$2:$C$1036,Overall!A10) -> 6 | C10: =SUMIFS(Rounds!$D$2:$D$1036,Rounds!$C$2:$C$1036,Overall!A10) -> 15850 | D10: =_xlfn.MINIFS(Rounds!$E$2:$E$1036,Rounds!$C$2:$C$1036,Overall!A10) -> 422 | E10: =_xlfn.MAXIFS(Rounds!$E$2:$E$1036,Rounds!$C$2:$C$1036,Overall!A10) -> 476 | H10: =COUNTIFS(Rounds!$C$2:$C$1036,Overall!A10,Rounds!$F$2:$F$1036,Overall!$H$1) -> 0 | I10: =COUNTIFS(Rounds!$C$2:$C$1036,Overall!A10,Rounds!$F$2:$F$1036,Overall!$I$1) -> 0 | J10: =COUNTIFS(Rounds!$C$2:$C$1036,Overall!A10,Rounds!$F$2:$F$1036,Overall!$J$1) -> 3 | K10: =COUNTIFS(Rounds!$C$2:$C$1036,Overall!A10,Rounds!$F$2:$F$1036,Overall!$K$1) -> 3 | L10: =COUNTIFS(Rounds!$C$2:$C$1036,Overall!A10,Rounds!$F$2:$F$1036,Overall!$L$1) -> 0 | M10: =COUNTIFS(Rounds!$C$2:$C$1036,Overall!A10,Rounds!$F$2:$F$1036,Overall!$M$1) -> 0 | N10: =COUNTIFS(Rounds!$C$2:$C$1036,Overall!A10,Rounds!$F$2:$F$1036,Overall!$N$1) -> 0 | O10: =COUNTIFS(Rounds!$C$2:$C$1036,Overall!A10,Rounds!$F$2:$F$1036,Overall!$O$1) -> 0 | P10: =COUNTIFS(Rounds!$C$2:$C$1036,Overall!A10,Rounds!$F$2:$F$1036,Overall!$P$1) -> 0 | Q10: =COUNTIFS(Rounds!$C$2:$C$1036,Overall!A10,Rounds!$F$2:$F$1036,Overall!$Q$1) -> 0 | R10: =COUNTIFS(Rounds!$C$2:$C$1036,Overall!A10,Rounds!$F$2:$F$1036,Overall!$R$1) -> 0 | S10: =COUNTIFS(Rounds!$C$2:$C$1036,Overall!A10,Rounds!$F$2:$F$1036,Overall!$S$1) -> 0 | T10: =COUNTIFS(Rounds!$C$2:$C$1036,Overall!A10,Rounds!$F$2:$F$1036,Overall!$T$1) -> 0 | U10: =COUNTIFS(Rounds!$C$2:$C$1036,Overall!A10,Rounds!$F$2:$F$1036,Overall!$U$1) -> 0
A11: No Program Specified | B11: =COUNTIFS(Rounds!$C$2:$C$1036,Overall!A11) -> 167 | C11: =SUMIFS(Rounds!$D$2:$D$1036,Rounds!$C$2:$C$1036,Overall!A11) -> 495597 | D11: =_xlfn.MINIFS(Rounds!$E$2:$E$1036,Rounds!$C$2:$C$1036,Overall!A11) -> 413 | E11: =_xlfn.MAXIFS(Rounds!$E$2:$E$1036,Rounds!$C$2:$C$1036,Overall!A11) -> 886 | H11: =COUNTIFS(Rounds!$C$2:$C$1036,Overall!A11,Rounds!$F$2:$F$1036,Overall!$H$1) -> 0 | I11: =COUNTIFS(Rounds!$C$2:$C$1036,Overall!A11,Rounds!$F$2:$F$1036,Overall!$I$1) -> 0 | J11: =COUNTIFS(Rounds!$C$2:$C$1036,Overall!A11,Rounds!$F$2:$F$1036,Overall!$J$1) -> 0 | K11: =COUNTIFS(Rounds!$C$2:$C$1036,Overall!A11,Rounds!$F$2:$F$1036,Overall!$K$1) -> 17 | L11: =COUNTIFS(Rounds!$C$2:$C$1036,Overall!A11,Rounds!$F$2:$F$1036,Overall!$L$1) -> 11 | M11: =COUNTIFS(Rounds!$C$2:$C$1036,Overall!A11,Rounds!$F$2:$F$1036,Overall!$M$1) -> 0 | N11: =COUNTIFS(Rounds!$C$2:$C$1036,Overall!A11,Rounds!$F$2:$F$1036,Overall!$N$1) -> 16 | O11: =COUNTIFS(Rounds!$C$2:$C$1036,Overall!A11,Rounds!$F$2:$F$1036,Overall!$O$1) -> 24 | P11: =COUNTIFS(Rounds!$C$2:$C$1036,Overall!A11,Rounds!$F$2:$F$1036,Overall!$P$1) -> 25 | Q11: =COUNTIFS(Rounds!$C$2:$C$1036,Overall!A11,Rounds!$F$2:$F$1036,Overall!$Q$1) -> 26 | R11: =COUNTIFS(Rounds!$C$2:$C$1036,Overall!A11,Rounds!$F$2:$F$1036,Overall!$R$1) -> 26 | S11: =COUNTIFS(Rounds!$C$2:$C$1036,Overall!A11,Rounds!$F$2:$F$1036,Overall!$S$1) -> 22 | T11: =COUNTIFS(Rounds!$C$2:$C$1036,Overall!A11,Rounds!$F$2:$F$1036,Overall!$T$1) -> 0 | U11: =COUNTIFS(Rounds!$C$2:$C$1036,Overall!A11,Rounds!$F$2:$F$1036,Overall!$U$1) -> 0
A12: Provincial Nominee Program | B12: =COUNTIFS(Rounds!$C$2:$C$1036,Overall!A12) -> 107 | C12: =SUMIFS(Rounds!$D$2:$D$1036,Rounds!$C$2:$C$1036,Overall!A12) -> 67519 | D12: =_xlfn.MINIFS(Rounds!$E$2:$E$1036,Rounds!$C$2:$C$1036,Overall!A12) -> 663 | E12: =_xlfn.MAXIFS(Rounds!$E$2:$E$1036,Rounds!$C$2:$C$1036,Overall!A12) -> 902 | H12: =COUNTIFS(Rounds!$C$2:$C$1036,Overall!A12,Rounds!$F$2:$F$1036,Overall!$H$1) -> 12 | I12: =COUNTIFS(Rounds!$C$2:$C$1036,Overall!A12,Rounds!$F$2:$F$1036,Overall!$I$1) -> 24 | J12: =COUNTIFS(Rounds!$C$2:$C$1036,Overall!A12,Rounds!$F$2:$F$1036,Overall!$J$1) -> 14 | K12: =COUNTIFS(Rounds!$C$2:$C$1036,Overall!A12,Rounds!$F$2:$F$1036,Overall!$K$1) -> 5 | L12: =COUNTIFS(Rounds!$C$2:$C$1036,Overall!A12,Rounds!$F$2:$F$1036,Overall!$L$1) -> 13 | M12: =COUNTIFS(Rounds!$C$2:$C$1036,Overall!A12,Rounds!$F$2:$F$1036,Overall!$M$1) -> 25 | N12: =COUNTIFS(Rounds!$C$2:$C$1036,Overall!A12,Rounds!$F$2:$F$1036,Overall!$N$1) -> 10 | O12: =COUNTIFS(Rounds!$C$2:$C$1036,Overall!A12,Rounds!$F$2:$F$1036,Overall!$O$1) -> 0 | P12: =COUNTIFS(Rounds!$C$2:$C$1036,Overall!A12,Rounds!$F$2:$F$1036,Overall!$P$1) -> 1 | Q12: =COUNTIFS(Rounds!$C$2:$C$1036,Overall!A12,Rounds!$F$2:$F$1036,Overall!$Q$1) -> 2 | R12: =COUNTIFS(Rounds!$C$2:$C$1036,Overall!A12,Rounds!$F$2:$F$1036,Overall!$R$1) -> 1 | S12: =COUNTIFS(Rounds!$C$2:$C$1036,Overall!A12,Rounds!$F$2:$F$1036,Overall!$S$1) -> 0 | T12: =COUNTIFS(Rounds!$C$2:$C$1036,Overall!A12,Rounds!$F$2:$F$1036,Overall!$T$1) -> 0 | U12: =COUNTIFS(Rounds!$C$2:$C$1036,Overall!A12,Rounds!$F$2:$F$1036,Overall!$U$1) -> 0
A13: STEM occupations (Version 1) | B13: =COUNTIFS(Rounds!$C$2:$C$1036,Overall!A13) -> 3 | C13: =SUMIFS(Rounds!$D$2:$D$1036,Rounds!$C$2:$C$1036,Overall!A13) -> 10900 | D13: =_xlfn.MINIFS(Rounds!$E$2:$E$1036,Rounds!$C$2:$C$1036,Overall!A13) -> 481 | E13: =_xlfn.MAXIFS(Rounds!$E$2:$E$1036,Rounds!$C$2:$C$1036,Overall!A13) -> 491 | H13: =COUNTIFS(Rounds!$C$2:$C$1036,Overall!A13,Rounds!$F$2:$F$1036,Overall!$H$1) -> 0 | I13: =COUNTIFS(Rounds!$C$2:$C$1036,Overall!A13,Rounds!$F$2:$F$1036,Overall!$I$1) -> 0 | J13: =COUNTIFS(Rounds!$C$2:$C$1036,Overall!A13,Rounds!$F$2:$F$1036,Overall!$J$1) -> 1 | K13: =COUNTIFS(Rounds!$C$2:$C$1036,Overall!A13,Rounds!$F$2:$F$1036,Overall!$K$1) -> 2 | L13: =COUNTIFS(Rounds!$C$2:$C$1036,Overall!A13,Rounds!$F$2:$F$1036,Overall!$L$1) -> 0 | M13: =COUNTIFS(Rounds!$C$2:$C$1036,Overall!A13,Rounds!$F$2:$F$1036,Overall!$M$1) -> 0 | N13: =COUNTIFS(Rounds!$C$2:$C$1036,Overall!A13,Rounds!$F$2:$F$1036,Overall!$N$1) -> 0 | O13: =COUNTIFS(Rounds!$C$2:$C$1036,Overall!A13,Rounds!$F$2:$F$1036,Overall!$O$1) -> 0 | P13: =COUNTIFS(Rounds!$C$2:$C$1036,Overall!A13,Rounds!$F$2:$F$1036,Overall!$P$1) -> 0 | Q13: =COUNTIFS(Rounds!$C$2:$C$1036,Overall!A13,Rounds!$F$2:$F$1036,Overall!$Q$1) -> 0 | R13: =COUNTIFS(Rounds!$C$2:$C$1036,Overall!A13,Rounds!$F$2:$F$1036,Overall!$R$1) -> 0 | S13: =COUNTIFS(Rounds!$C$2:$C$1036,Overall!A13,Rounds!$F$2:$F$1036,Overall!$S$1) -> 0 | T13: =COUNTIFS(Rounds!$C$2:$C$1036,Overall!A13,Rounds!$F$2:$F$1036,Overall!$T$1) -> 0 | U13: =COUNTIFS(Rounds!$C$2:$C$1036,Overall!A13,Rounds!$F$2:$F$1036,Overall!$U$1) -> 0
